Workbook

Sheet 0 OKU BENI
A1: YEDİHİLAL İSTANBUL — TEŞKİLATLANMA BİRİMİ · ÇALIŞMA DOSYASI
B3: ◐ LOGO BURAYA | C3: YEDİHİLAL — Yedi Tepeden Yedi Kıtaya
C4: İLKELERİMİZ: İman · İlim · İstişare · İrfan · Hikmet · Ahlak · Hareket
C5: «Nizamsız hâk, nizamlı bâtıla mağlûb olur.» — Mustafa Sabri Efendi
C6: «Biz zaferden değil seferden sorumluyuz; gayret bizden, başarı Allah'tan.»
C7: GAYEMİZ: Yaşantısı ile topluma örneklik teşkil eden, inancımızın yüklediği sorumlulukları üstlenen öncü bir kuşağın yetişmesine katkı sağlamak.
B8: ↑ LOGO: Kurumsal kimliğe uygun YediHilal logosunu bu kutuya yapıştır (Ekle → Resim). Aynısını el kitapçığının kapağına da koy.
B10: Sorumlu | C10: Abdülkadir Bey — İstanbul İl Teşkilatlanma Birimi Başkanı
B11: Görev süresi | C11: 2026–2029 (2-3 yıllık uzun vadeli görev)
B12: Dosya | C12: v3 · 11 Temmuz 2026 · 39 ilçe / 4 bölge yapısına göre revize edildi
B13: Yanında gelen dosyalar | C13: 1) İlçe Karne ve Dashboard Sistemi (ayrı Excel) 2) Teşkilatlanma Birimi El Kitabı (Word)
B15: BU DOSYADA NE DEĞİŞTİ (v2 → v3)
A16: ESKİ MANTIK (yanlıştı): Bölgeler, sadece temsilciliğimiz OLAN 9 ilçeye göre kuruluyordu. Bu, teşkilatın gözünü kör eder — olmadığın yeri hiç görmezsin. YENİ MANTIK: İstanbul'un 39 İLÇESİNİN TAMAMI sisteme girdi. 4 bölge, coğrafi hatlara göre kuruldu (Haliç · Trakya · Boğaz · Marmara). Her ilçenin bir bölgesi, her bölgenin bir takipçisi var. Temsilciliğimiz olan 9 ilçe KOYU YEŞİL. Kalan 30 ilçe boş — ve o boşluk, bölge takipçisinin GÖREVİDİR. Artık kimse 'benim bölgemde iş yok' diyemez: 30 boş ilçe, 30 açık görev demektir.
B18: 4 BÖLGE — ÖZET
B19: Bölge | C19: Yaka | D19: İlçe / mevcut temsilcilik | E19: Takipçi
B20: BÖLGE 1 — HALİÇ HATTI | C20: AVRUPA | D20: 10 ilçe · 1 temsilcilik | E20: BOŞ
B21: BÖLGE 2 — TRAKYA HATTI | C21: AVRUPA | D21: 15 ilçe · 3 temsilcilik | E21: BOŞ
B22: BÖLGE 3 — BOĞAZ HATTI | C22: ANADOLU | D22: 6 ilçe · 2 temsilcilik | E22: Nusret Onur Anlı
B23: BÖLGE 4 — MARMARA HATTI | C23: ANADOLU | D23: 8 ilçe · 3 temsilcilik | E23: Mehmet Menteş
B25: KİM NEYİ DOLDURUR? (bu tabloyu ekibe dağıt — en çok karışan konu budur)
B26: Sekme | C26: VERİYİ KİM GİRER | D26: Ne sıklıkla | E26: Kimse dokunmaz
B27: 1 Panel | C27: Kimse — otomatik dolar | D27: Anlık | E27: Tüm formüller
B28: 2 Vizyon 3 Yıl | C28: Birim Başkanı (Abdülkadir Bey) | D28: Yılda 1 kez gözden geçirilir | E28: —
B29: 3 Birim Planı | C29: Birim Başkanı | D29: Dönem başında | E29: —
B30: 4 Reisin İstekleri | C30: Birim Başkanı | D30: Haftalık durum güncellemesi | E30: —
B31: 5 Ekip Değerlendirme | C31: Birim Başkanı (gizli — ekibe açılmaz) | D31: 3 ayda 1 | E31: —
B32: 6 Komisyon Birimleri | C32: Birim Başkanı | D32: Görev dağılımı yapılırken | E32: —
B33: 7 Bölge Yapısı | C33: Birim Başkanı (takipçi ataması) | D33: Değişiklik oldukça | E33: —
B34: 8 İlçe Haritası | C34: Sekreterya (yeni temsilcilik açılınca rengi değişir) | D34: Açılış oldukça | E34: —
B35: 9 İlçe Envanteri | C35: BÖLGE TAKİPÇİLERİ (kendi bölgesinin satırları) | D35: Aylık | E35: Bölge sütunu
B36: 10 Yeni Teşkilat Hattı | C36: Yeni Teşkilat Sorumlusu (Oğuzhan) + bölge takipçileri | D36: Haftalık | E36: —
B37: 11 Aday Havuzu | C37: Yeni Teşkilat Sorumlusu + Birim Başkanı (birlikte puanlar) | D37: Her yeni isimde | E37: PUAN ve ÖNERİLEN GÖREV sütunları
... B45: AYRI DOSYA: Karne | C45: Arayan görevli girer, Sekreterya arşivler | D45: Aylık | E45: Tüm PUAN sütunları
A47: ALTIN KURAL: GRİ ve FORMÜLLÜ hiçbir hücreye elle rakam yazılmaz. Bir kişi tek bir formülü ezerse tüm dosya sessizce yalan söylemeye başlar. Formül bozulduysa yeniden yazdırmak dakikalar sürer — ama yanlış rakamla alınmış bir karar aylar sürer.
B49: RENK KODU
B50: Mavi yazı | C50: Senin dolduracağın hücre
B51: Sarı dolgu | C51: Karar bekleyen / kritik varsayım
B52: KOYU YEŞİL | C52: Temsilciliğimiz OLAN ilçe
B53: Bölge rengi | C53: Temsilciliğimiz OLMAYAN ilçe — bölge takipçisinin görevi
B54: Siyah yazı | C54: Formül — dokunma

Sheet 1 Panel
A1: PANEL — TEK BAKIŞTA İSTANBUL
A3: KAPSAMA DURUMU
B4: Gösterge | C4: Değer | D4: Hedef | E4: Yorum
B5: İstanbul'daki toplam ilçe | C5: =COUNTA('9 Ilce Envanteri'!C3:C41) -> 39 | D5: 39 | E5: Tamamı sistemde
B6: Temsilciliğimiz OLAN ilçe | C6: =COUNTIF('9 Ilce Envanteri'!D3:D41,"MEVCUT") -> 9 | E6: Koyu yeşil ilçeler
B7: Temsilciliğimiz OLMAYAN ilçe | C7: =COUNTIF('9 Ilce Envanteri'!D3:D41,"HEDEF") -> 30 | E7: 30 boş ilçe = 30 açık görev
B8: İSTANBUL KAPSAMA ORANI | C8: =IFERROR(COUNTIF('9 Ilce Envanteri'!D3:D41,"MEVCUT")/COUNTA('9 Ilce Envanteri'!C3:C41),0) -> 0.23076923 | D8: 0.5 | E8: Gerçek başarı ölçütü bu. Bugün: dörtte biri bile değil.
B9: Öncelik 1 (yakın vadede açılacak) ilçe | C9: =COUNTIFS('9 Ilce Envanteri'!D3:D41,"HEDEF",'9 Ilce Envanteri'!G3:G41,1) -> 15 | E9: Enerjini buraya yığ
B10: KRİTİK + YÜKSEK riskli temsilcilik | C10: =COUNTIF('9 Ilce Envanteri'!F3:F41,"KRİTİK")+COUNTIF('9 Ilce Envanteri'!F3:F41,"Yüksek") -> 5 | D10: 0 | E10: Mevcut 9'un yarısından fazlası
B11: Bölge sayısı | C11: =COUNTA('7 Bolge Yapisi'!B4:B7) -> 4 | D11: 4 | E11: Haliç · Trakya · Boğaz · Marmara
B12: Takipçisi ATANMAMIŞ bölge | C12: =COUNTIF('7 Bolge Yapisi'!D4:D7,"BOŞ") -> 2 | D12: 0 | E12: Boş bölge = 25 ilçe sahipsiz
B13: Aday havuzundaki kişi | C13: =COUNTA('11 Aday Havuzu'!B6:B25) -> 0 | D13: 30 | E13: Yeni teşkilat buradan çıkar
B14: Görev verilebilir aday (≥70 puan) | C14: =COUNTIF('11 Aday Havuzu'!R6:R25,">=70") -> 0 | E14: Temsilci/birim başkanı adayları
B15: Komisyonun FİİLEN aktif üyesi | C15: =COUNTIF('5 Ekip Degerlendirme'!G4:G13,"Aktif") -> 4 | D15: 7 | E15: 39 ilçelik bir şehir bu kadroyla yönetilmez
A17: BÖLGE BAZINDA KAPSAMA
B18: Bölge | C18: İlçe | D18: Mevcut | E18: Kapsama % | F18: Takipçi
B19: BÖLGE 1 — HALİÇ HATTI | C19: 10 | D19: 1 | E19: =IFERROR(D19/C19,0) -> 0.1 | F19: BOŞ
B20: BÖLGE 2 — TRAKYA HATTI | C20: 15 | D20: 3 | E20: =IFERROR(D20/C20,0) -> 0.2 | F20: BOŞ
B21: BÖLGE 3 — BOĞAZ HATTI | C21: 6 | D21: 2 | E21: =IFERROR(D21/C21,0) -> 0.33333333 | F21: Nusret Onur Anlı
B22: BÖLGE 4 — MARMARA HATTI | C22: 8 | D22: 3 | E22: =IFERROR(D22/C22,0) -> 0.375 | F22: Mehmet Menteş
B23: İSTANBUL TOPLAM | C23: =SUM(C19:C22) -> 39 | D23: =SUM(D19:D22) -> 9 | E23: =IFERROR(D23/C23,0) -> 0.23076923
A25: BU AY YAPILMASI ŞART OLAN 5 İŞ
A26: # | B26: İş | C26: Termin | D26: Durum | E26: Not
A27: 1 | B27: Bölge 1 (Haliç) ve Bölge 2 (Trakya) takipçilerini bul | C27: 30.09.2026 | D27: Başlamadı | E27: 25 ilçe şu an sahipsiz — en acil iş bu
A28: 2 | B28: Pendik'te asil temsilci meselesini çöz | C28: 30.08.2026 | D28: Başlamadı | E28: Vekâlet uzarsa ekip dağılır
A29: 3 | B29: Öncelik 1 ilçelerde koordinatör arayışını başlat | C29: 30.09.2026 | D29: Başlamadı | E29: Sekme 10 — huninin 1. aşaması
A30: 4 | B30: Karne + ziyaret formunu Reis'e onaylat | C30: 31.07.2026 | D30: Taslak hazır | E30: Ayrı dosya: Karne Sistemi
A31: 5 | B31: Temsilciler toplantısını yeniden başlat | C31: 31.07.2026 | D31: Karar bekliyor | E31: Mayıs-Haziran boşluğu kapanmalı

Sheet 2 Vizyon 3 Yil
A1: 2026–2029 ÜÇ YILLIK TEŞKİLATLANMA VİZYONU — 39 İLÇELİK İSTANBUL
A2: Yıl | B2: Aşama | C2: Ana fikir | D2: Somut hedefler | E2: Ölçüt | F2: Bitmeden sonrakine geçme
A3: 1. Yıl 2026-27 | B3: KONSOLİDASYON | C3: Elindekini kurtar, sistemi kur. Kapsama oranını artırmadan önce kaliteyi ayağa kaldır. | D3: · Mevcut 9 temsilcilik aylık rapor veriyor · 4 bölgenin 4'ünde de takipçi var · Kritik 4 temsilcilik (Pendik, Üsküdar, Kağıthane, Ümraniye) kurtarıldı · Karne sistemi 12 ay kesintisiz işledi · İcra ekibi 4 → 7-8 kişi · Öncelik 1 ilçelerin tamamında koordinatör arayışı başladı · 2-4 yeni temsilcilik (kadrosu tam olan) | E3: · Kapsama: 9/39 → 11-13/39 · Ortalama karne puanı ≥ 60 · Rapor geri dönüşü %100 | F3: 4 bölgenin de takipçisi olmadan 2. yıla geçme.
A4: 2. Yıl 2027-28 | B4: GENİŞLEME | C4: Sistem oturdu. Şimdi huniyi çalıştır: Öncelik 1 ve 2 ilçelerini sırayla aç. | D4: · Aday havuzu 50+ isim · 6-8 yeni ilçe temsilciliği · Her bölgede en az 4 temsilcilik · Mahalleleşme pilotu (Kartal, Kadıköy) · Her temsilcilikte ortaokul + lise birimi | E4: · Kapsama: 18-20/39 (yaklaşık yarısı) · Kapanan temsilcilik: 0 | F4: Yeni açılan bir temsilcilik ilk yılında C sınıfına düşüyorsa açılış kriterlerin zayıf — dur ve sıkılaştır.
A5: 3. Yıl 2028-29 | B5: KURUMSALLAŞMA | C5: Senden sonra da yürüyecek bir yapı bırak. Teşkilat kişiye değil sisteme bağlansın. | D5: · Bölge takipçileri kendi başına çalışıyor · Her temsilcilikte 'ikinci adam' yetişti · Yazılı süreç kılavuzu (açılış-ziyaret-karne-devir) · Kendi yerine 2 halef adayı | E5: · Kapsama: 25-30/39 · Sen 2 hafta yokken hiçbir iş aksamıyor | F5: Halef yetiştirmeden görevi bırakma.
A7: 39 İLÇELİK GERÇEK: Bugün İstanbul'un %23'ündeyiz (9/39). Reis'in '20 temsilcilik' hedefi aslında %51 kapsama demek — yani İstanbul'un yarısı. Bu, 1 yılın işi değil; 2-3 yılın işidir ve tam da senin görev sürene denk gelir. Hedefi reddetme, TAKVİME YAY: 1. yıl 11-13, 2. yıl 18-20, 3. yıl 25-30. Böylece hem Reis'in rakamını tutturursun hem de hiçbiri dağılmaz.

Sheet 3 Birim Plani
A1: TEŞKİLATLANMA BİRİMİ 2026/27 PLANI — 8 BAŞLIK
A3: 1) MİSYON
A4: İstanbul'un 39 ilçesinin tamamında YediHilal teşkilatını insan merkezli olarak kurmak, ayakta tutmak ve büyütmek. Bizim işimiz temsilcilik 'açmak' değil; açılan her temsilciliğin kendi ayağı üzerinde duracak kadroya, düzenli toplantıya, gençlik birimine ve mali sisteme kavuşmasını sağlamaktır. Nicelik değil nitelik esastır. Bu birim, İl Yönetimi ile temsilcilikler arasındaki tek ve düzenli köprüdür; ayrıca İstanbul'daki diğer STK'larla kurumsal ilişkilerin teşkilat ayağını yürütür.
A6: 2) 2026–27 HEDEFLERİ
A7: # | B7: Hedef | C7: Ölçülebilir çıktı | D7: Termin | E7: Sorumlu
A8: 1 | B8: 4 bölgenin 4'üne de takipçi atanması | C8: Haliç ve Trakya hatlarına isim bulunması | D8: 30.09.2026 | E8: Birim Başkanı
A9: 2 | B9: Takip sisteminin kurulması | C9: Bölge + karne + ziyaret formu işliyor | D9: 30.09.2026 | E9: Başkan + Sekreterya
A10: 3 | B10: Mevcut 9 temsilciliğin aktifleşmesi | C10: 9/9 aylık rapor + haftalık YK toplantısı | D10: 31.12.2026 | E10: Bölge takipçileri
A11: 4 | B11: Kritik 4 temsilcilikte kadro yenileme | C11: Pendik, Üsküdar, Kağıthane, Ümraniye | D11: 31.10.2026 | E11: Başkan + Yeni Teşkilat
A12: 5 | B12: İcra ekibinin genişletilmesi | C12: Fiilen aktif üye 4 → 7-8 | D12: 30.09.2026 | E12: Birim Başkanı
A13: 6 | B13: Öncelik 1 ilçelerde koordinatör arayışı | C13: 15 ilçenin tamamında en az 1 isimle temas | D13: 31.12.2026 | E13: Yeni Teşkilat + bölge takipçileri
A14: 7 | B14: Aday havuzunun kurulması | C14: En az 30 isim, puanlanmış | D14: 31.12.2026 | E14: Yeni Teşkilat
A15: 8 | B15: Yeni ilçe temsilciliği | C15: Kadrosu tam 2-4 ilçe | D15: Dönem sonu | E15: Yeni Teşkilat
A16: 9 | B16: Her mevcut temsilciliğe en az 1 ziyaret | C16: 9 ziyaret formu, YK üyesi eşliğinde | D16: 30.09.2026 | E16: Ziyaret Birimi
A17: 10 | B17: İstanbul İl Teşkilat Kampı | C17: Eylül-Ekim, dönem planlama çıktısı | D17: Ekim 2026 | E17: Başkan + Ömer Faruk
A18: 11 | B18: STK ilişkileri hattı | C18: 6 kurumla düzenli temas, 2 ortak program | D18: 31.12.2026 | E18: STK Birimi
A20: 3) HAFTALIK YAPILACAKLAR
A21: # | B21: İş | C21: Nasıl | D21: Gün | E21: Çıktı
A22: 1 | B22: Komisyon toplantısı | C22: Gündemli, tutanaklı, karar tablolu (Sekme 18) | D22: Pazartesi 21:00 | E22: Tutanak
A23: 2 | B23: Bölge turu | C23: Her takipçi kendi bölgesindeki MEVCUT temsilcileri arar | D23: Salı–Çarşamba | E23: Bölge özeti
A24: 3 | B24: Hedef ilçe teması | C24: Her takipçi kendi bölgesindeki 1 HEDEF ilçede yeni temas kurar | D24: Hafta içi | E24: Aday havuzuna giriş
A25: 4 | B25: Saha yarım günü | C25: Perşembe işten erken çık: ziyaret + telefon trafiği | D25: Perşembe öğleden sonra | E25: Temas kaydı
A26: 5 | B26: Dernek tam günü | C26: Gelen-giden ve aday görüşmeleri, temsilcilik ziyareti | D26: Cumartesi | E26: Aday havuzu girişi
A27: 6 | B27: Reis'e haftalık özet | C27: 5 madde: yapılan / yapılmayan / engel / karar / rakam | D27: Cuma | E27: Haftalık özet
A29: 4) AYLIK YAPILACAKLAR
A30: # | B30: İş | C30: Nasıl | D30: Zaman | E30: Çıktı
A31: 1 | B31: Temsilciler Aylık Toplantısı | C31: Başkan düzeyinde katılım zorunlu | D31: Ayın ilk haftası | E31: Tutanak + yoklama
A32: 2 | B32: Faaliyet raporlarının toplanması | C32: Sekme 17 formatı; Sekreterya toplar | D32: Ayın son 3 günü | E32: 9 dolu form
A33: 3 | B33: Karne aramaları ve puanlama | C33: Ayrı dosya: Karne Sistemi. Arayan görevli 12 soruyu sorar. | D33: Ayın son haftası | E33: Karne + dashboard
A34: 4 | B34: En az 2 temsilcilik ziyareti | C34: Cumartesi sabahı — Çağın Sancaktarı ders saatinde | D34: Ay içinde | E34: 2 ziyaret formu
A35: 5 | B35: D sınıfı temsilciliklerle birebir | C35: 50 puan altındakilerle yüz yüze | D35: Karne sonrası 10 gün | E35: Görüşme notu
A36: 6 | B36: Hedef ilçe ilerleme oturumu | C36: 30 hedef ilçenin huni aşamaları gözden geçirilir | D36: Ayda 1 | E36: Sekme 10 güncel
A37: 7 | B37: Aday değerlendirme oturumu | C37: Yeni isimler puanlanır, görev önerilir | D37: Ayda 1 | E37: Sekme 11 güncel
A38: 8 | B38: Reis'e aylık teşkilat raporu | C38: Karne + kapsama + ziyaret + risk | D38: Ayın ilk haftası | E38: Aylık rapor
A40: 5) YILLIK PROJELER
A41: # | B41: Proje | C41: İçerik | D41: Dönem | E41: Sorumlu
A42: 1 | B42: 39 İlçe Kapsama Programı | C42: İstanbul'un tamamının haritalanması ve sıralı açılış planı | D42: Tüm dönem | E42: Yeni Teşkilat
A43: 2 | B43: İstanbul İl Teşkilat Kampı | C43: Dönem değerlendirme + planlama | D43: Eylül–Ekim 2026 | E43: Başkan
A44: 3 | B44: Bölge Takipçiliği Sistemi | C44: 4 hat, 4 takipçi, yazılı görev tanımı | D44: Temmuz–Eylül | E44: Başkan
A45: 4 | B45: Karne ve Ödül Sistemi | C45: Yıl sonu en yüksek 3 temsilcilik | D45: Aralık 2026 | E45: Veri ve Raporlama
...

Sheet 4 Reisin Istekleri
A1: İL BAŞKANI'NIN TALEPLERİ — GERÇEKÇİLİK SÜZGECİ VE FAZLAMA
A2: Hiçbir talebe 'hayır' denmiyor — sıraya konuyor. Teşkilatta reddedilen talep sorun çıkarır; sıraya konan talep saygı görür.
A3: # | B3: Talep | C3: Gerçekçilik | D3: Faz | E3: Somut çıktı | F3: Sorumlu | G3: Termin | H3: Reis'e cevabın
A4: 1 | B4: Mevcut temsilciliklerle görüşülmesi | C4: Gerçekçi | D4: FAZ 1 | E4: 9 temsilciyle birebir tanışma | F4: Başkan | G4: 31.07.2026 | H4: İlk 3 haftada tamamı.
A5: 2 | B5: Temsilciliklerden her ay rapor alınması | C5: Gerçekçi | D5: FAZ 1 | E5: Aylık faaliyet formu, %100 geri dönüş | F5: Sekreterya | G5: Her ay | H5: Form standardı hazır (Sekme 17).
A6: 3 | B6: Temsilcilikler toplantısının planlanması | C6: Gerçekçi | D6: FAZ 1 | E6: Temmuz-Eylül takvimi + format kararı | F6: Başkan | G6: 20.07.2026 | H6: Format kararını sizinle netleştirelim: sabah namazı mı, akşam 19:00 mı?
A7: 4 | B7: Çadır kampına katılacak temsilci sayısının artırılması | C7: Gerçekçi | D7: FAZ 1 | E7: 9/9 temsilci düzeyinde katılım | F7: Bölge takipçileri | G7: Kamp öncesi | H7: Temsilci gelmezse ekibi hiç gelmez.
A8: 5 | B8: Çadır kampına 300 kişi ile gidilmesi | C8: ABARTILI | D8: FAZ 1 (revize) | E8: Temsilcilik bazında TAAHHÜT toplanır, çıkan rakam hedef olur | F8: Bölge takipçileri | G8: Kamp tarihi | H8: Geçen yılın rakamı nedir? 9 temsilcilikten 300 = ilçe başı 33 kişi. Taahhüt toplayıp gerçek rakamı size vereyim.
A9: 6 | B9: Temsilcilik ziyareti planlanması (YK dahil) | C9: Gerçekçi | D9: FAZ 1 | E9: Ziyaret takvimi + standart form | F9: Ziyaret Birimi | G9: Eylül sonu | H9: Cumartesi sabahları — Çağın Sancaktarı ders saati, herkes orada.
A10: 7 | B10: İstanbul İl Teşkilat Kampı (Eylül-Ekim) | C10: Gerçekçi | D10: FAZ 2 | E10: Tarih, mekân, bütçe, program akışı | F10: Başkan | G10: 15.08 ön plan | H10: Ekim'e koyalım; Eylül okul açılışıyla çakışıyor.
A11: 8 | B11: İlk dönem sonu 20 temsilcilik hedefi | C11: ABARTILI | D11: FAZ 2-3 | E11: 1. yıl: 2-4 yeni · 2. yıl: 6-8 · 3. yıl: kalanlar | F11: Yeni Teşkilat | G11: Dönem sonu | H11: 20 temsilcilik = İstanbul'un %51'i. Bu 1 yılın değil, 3 yılın işi — ki görev sürem de 3 yıl. Takvime yayalım, hedefi tutturayım.
A12: 9 | B12: İcra ekibinin genişletilmesi | C12: Gerçekçi — EN KRİTİK | D12: FAZ 1 | E12: 2 bölge takipçisi + alt birim sorumluları | F12: Başkan | G12: 30.09.2026 | H12: Haliç ve Trakya hatlarında 25 ilçe SAHİPSİZ. Bu, listedeki her şeyin ön şartı.
A13: 10 | B13: Haftalık birim toplantılarının yapılması | C13: Gerçekçi | D13: FAZ 1 | E13: Pazartesi 21:00, gündemli, tutanaklı | F13: Sekreterya | G13: Haftalık | H13: Zaten var. Standardı yükselttim.
A14: 11 | B14: YK rehberini gözden geçirip isim önerilmesi | C14: Gerçekçi | D14: FAZ 2 | E14: Boş kadro haritası + her kadroya 2 aday | F14: Başkan | G14: 31.08.2026 | H14: Aday havuzu kurulduktan sonra anlamlı olur.
A15: 12 | B15: Temsilcilik performans puanlama sistemi | C15: Gerçekçi | D15: FAZ 1 | E15: 12 kriter, 100 puan, A/B/C/D + dashboard | F15: Veri ve Raporlama | G15: 31.07.2026 | H15: HAZIR — ayrı Karne dosyası. Mevcut karnenizin motorlaştırılmış hâli.
... A17: 14 | B17: Birimin 8 başlıkta planlanması | C17: Gerçekçi | D17: FAZ 1 | E17: Misyon/Hedef/Haftalık/Aylık/Yıllık/KPI/Sorumlu/Raporlama | F17: Başkan | G17: 31.07.2026 | H17: HAZIR — Sekme 3.
A19: FAZ TANIMI: FAZ 1 = Temmuz–Eylül (sistem kurulumu) · FAZ 2 = Ekim–Aralık (kadro + ilk yeni ilçeler) · FAZ 3 = 2027+ (asıl büyüme). Reis'e giderken bu tabloyu yazdır — 14 maddenin 14'üne de sahip çıkmış ama sıraya koymuş olursun.

Sheet 5 Ekip Degerlendirme
A1: KOMİSYON EKİBİ — GERÇEK KAPASİTE VE GÖREV TEVDİİ (gizli — ekibe açılmaz)
A2: Teşkilatta en pahalı hata, 'listede var ama fiilen yok' olan kişiye iş bağlamaktır. Herkes GERÇEK kapasitesine göre konumlandırıldı.
A3: # | B3: Kişi | C3: Gerçek durum | D3: Kapasite | E3: Verilecek görev / alt birim | F3: Sorumlu bölge | G3: Statü | H3: Neden bu görev | I3: Karar
A4: 1 | B4: Mücahit Tiryaki | C4: Sekreterimiz. Duyuru, tutanak, faaliyet formları, karneler. | D4: Yüksek — taşıyıcı | E4: SEKRETERYA BİRİMİ başkanı | F4: — | G4: Aktif | H4: Sistem işleri kişiye değil düzene bağlanır; en düzenli isim burada durmalı.
A5: 2 | B5: Oğuzhan Koçalak | C5: Yeni isim değerlendirme, gönüllü formu ilk görüşmeleri. | D5: Yüksek — insan kaynağı | E5: YENİ TEŞKİLAT BİRİMİ + İNSAN KIYMETLERİ | F5: 30 hedef ilçenin tamamı | G5: Aktif | H5: 'Olmadığımız ilçede insan bulma' işinin sahibi. Huninin sorumlusu.
A6: 3 | B6: Mehmet Menteş | C6: Temsilcilik ilişkileri, duyuru, katılım sayısı. Saha teması güçlü. | D6: Yüksek — saha | E6: BÖLGE TAKİPÇİSİ | F6: BÖLGE 4 — Marmara Hattı (8 ilçe / 3 mevcut) | G6: Aktif | H6: Zaten yaptığı iş bu; adı konuldu ve sınırı çizildi.
A7: 4 | B7: Nusret Onur Anlı | C7: YK'da yanında; her noktada gidip gelecek, destek olacak. | D7: Orta-Yüksek | E7: BÖLGE TAKİPÇİSİ | F7: BÖLGE 3 — Boğaz Hattı (6 ilçe / 2 mevcut) | G7: Aktif | H7: 'Her işte destek' profili bölge takipçiliğine birebir uyar: gez, ara, sor, raporla.
A8: 5 | B8: Serdar Alkurt | C8: Ziyaret olduğunda gelme potansiyeli var. | D8: Düşük-Orta — etkinlik bazlı | E8: ZİYARET VE DENETİM BİRİMİ üyesi | F8: Sabit bölge yok | G8: Yarı aktif | H8: Ziyaret olay bazlı iştir, süreklilik gerektirmez. Kapasitesine oturuyor.
A9: 6 | B9: Burak İncecik | C9: Gelip gidebilir, sekreterya yapabilir. | D9: Düşük-Orta — destek | E9: SEKRETERYA YEDEĞİ + Ziyaret Birimi | F9: Sabit bölge yok | G9: Yarı aktif | H9: Mücahit'e tek kişilik bağımlılığı bu isim kırar. Yedeksiz sistem çöker.
A10: 7 | B10: Eyüp Yazıcı | C10: Aktif değil — 'yok gibi düşünebiliriz'. | D10: Yok | E10: Görev VERİLMEZ. Programlara davet edilir. | F10: — | G10: Pasif | H10: Kapasitesi olmayana iş bağlamak, işi hiç yapmamaktan kötüdür.
A11: 8 | B11: Osman Savaş | C11: Aktif değil — daha önce görevden müsaade istemişti. | D11: Yok | E11: Onurlu şekilde uğurlanır; istişare listesinde kalır | F11: — | G11: Pasif | H11: Belirsizlik komisyonu yorar; toplantı yeter sayısını da şişirir.
A12: 9 | B12: Turan Çınar | C12: Tecrübeli büyüğümüz; geri çekilmiş. | D12: İstişare | E12: İSTİŞARE ÜYESİ — icra görevi yok | F12: — | G12: İstişare | H12: Tecrübe değerlidir ama icra yükü değildir. Ayda 1 istişareye çağır.
A13: 10 | B13: Ömer Faruk Balta | C13: İş yoğunluğu var; programlara katılabiliyor. | D13: Proje bazlı | E13: İL TEŞKİLAT KAMPI organizasyonu | F13: — | G13: Proje | H13: Sürekli görev kaldıramaz; tek seferlik büyük iş kaldırabilir.
B15: Aktif üye | C15: =COUNTIF(G4:G13,"Aktif") -> 4
B16: Yarı aktif | C16: =COUNTIF(G4:G13,"Yarı aktif") -> 2
B17: Pasif | C17: =COUNTIF(G4:G13,"Pasif") -> 2
B18: Fiilî iş gücü (Aktif + 0,5×Yarı) | C18: =COUNTIF(G4:G13,"Aktif")+0.5*COUNTIF(G4:G13,"Yarı aktif") -> 5
A20: YAPISAL TEŞHİS: Kâğıtta 10 kişi, fiilen 4 aktif + 2 yarı aktif. BÖLGE 1 (Haliç, 10 ilçe) ve BÖLGE 2 (Trakya, 15 ilçe) TAKİPÇİSİZ — yani İstanbul'un 25 ilçesi bugün hiç kimsenin sorumluluğunda değil. Reis'ten isteyeceğin '2 kaliteli isim' tam olarak bu iki koltuk içindir ve talebin somut gerekçesi budur: '25 ilçe sahipsiz.'

Sheet 6 Komisyon Birimleri
A1: TEŞKİLATLANMA KOMİSYONUNUN KENDİ ALT BİRİMLERİ — ÖNERİ
A2: Bugün komisyonun tek adlandırılmış birimi SEKRETERYA. Geri kalan her iş isimsiz duruyor — isimsiz iş, sahipsiz iştir. Aşağıdaki 8 alt birim, komisyonun yaptığı işleri isimlendirir. Kişi yetmiyorsa bir kişi 2 birim taşır; ama BİRİM İSİMSİZ KALMAZ. Böylece yeni biri geldiğinde 'sen şu birimin başındasın' denir, 'yardım et' denmez.
A3: # | B3: Alt birim | C3: Durum | D3: Ne iş yapar | E3: Haftalık işi | F3: Aylık işi | G3: Önerilen sorumlu | H3: Çıktısı
A4: 1 | B4: SEKRETERYA BİRİMİ | C4: VAR | D4: Toplantı duyuru ve tutanakları, arşiv, faaliyet formlarının toplanması, iletişim listelerinin güncelliği. | E4: Toplantı duyurusu + tutanak | F4: Faaliyet raporlarını toplama | G4: Mücahit Tiryaki | H4: Tutanak, arşiv, güncel liste
A5: 2 | B5: BÖLGE TAKİP BİRİMİ | C5: YENİ | D5: 4 bölgenin takibi. Her takipçi kendi bölgesindeki MEVCUT temsilcilikleri yönetir, HEDEF ilçelerde temas kurar. | E5: Bölge turu (arama) + bölge özeti | F5: Bölge raporu + 1 ziyaret | G5: 4 kişi (2'si BOŞ) | H5: Haftalık bölge özeti
A6: 3 | B6: YENİ TEŞKİLAT BİRİMİ | C6: YENİ | D6: 30 hedef ilçenin açılış hunisi. Koordinatör arayışı, tanışma toplantıları, kurucu heyet kurulumu. | E6: Huni aşamalarını güncelleme | F6: Kapsama raporu | G6: Oğuzhan Koçalak | H6: Yeni temsilcilik dosyası
A7: 4 | B7: İNSAN KIYMETLERİ BİRİMİ | C7: YENİ | D7: Aday havuzu. Gönüllü formu başvuruları, ilk görüşmeler, Nitelikli İnsan puanlaması, görev tevdii önerisi. | E7: Gelen başvurularla görüşme | F7: Aday değerlendirme oturumu | G7: Oğuzhan + Başkan | H7: Puanlanmış aday havuzu
A8: 5 | B8: ZİYARET VE DENETİM BİRİMİ | C8: YENİ | D8: Temsilcilik ziyaretleri. Standart form, YK üyesi eşliği, ziyaret raporu. | E8: — | F8: En az 2 ziyaret | G8: Serdar Alkurt + Burak İncecik | H8: Ziyaret formu ve raporu
A9: 6 | B9: VERİ VE RAPORLAMA BİRİMİ | C9: YENİ | D9: Karne aramaları, puanlama, dashboard, Reis'e giden raporlar. Excel dosyalarının bekçisi. | E9: Program katılım takibi | F9: Karne + dashboard + aylık rapor | G9: Mücahit + 1 yeni isim | H9: Aylık karne ve dashboard
A10: 7 | B10: EĞİTİM VE ORYANTASYON BİRİMİ | C10: YENİ | D10: Yeni temsilcilere ve yeni görevlilere YediHilal usulünün öğretilmesi. Rehber, el kitabı, ilk 30 gün programı. | E10: — | F10: Yeni görevli oryantasyonu | G10: Ömer Faruk Balta (proje bazlı) | H10: Oryantasyon dosyası
A11: 8 | B11: STK VE KURUMSAL İLİŞKİLER | C11: YENİ | D11: Diğer STK'lar, müftülükler, imamlar, İHL öğretmenleri, bilgi evleri ile temas. Yeni ilçelerin KAPISI burasıdır. | E11: 1 yeni kurumsal temas | F11: STK ziyareti | G11: Başkan (Abdülkadir Bey) | H11: STK ilişki tablosu
A13: NASIL UYGULANIR: Bu 8 birimi bir sonraki pazartesi toplantısında ilan et ve YAZILI olarak dağıt. Kişi sayısı yetmediği için bugün bir isim 2 birim taşıyacak — sorun değil. Önemli olan, her işin bir ADI ve bir SAHİBİ olması. Yeni bir kardeş ekibe katıldığında ona 'gel yardım et' demeyeceksin; 'Ziyaret ve Denetim Birimi'nin başındasın, görev tanımın şu' diyeceksin. Teşkilatta insanı tutan şey, görevin ağırlığı değil, görevin NETLİĞİDİR.

Sheet 7 Bolge Yapisi
A1: BÖLGE YAPISI — İSTANBUL'UN 39 İLÇESİ, 4 COĞRAFİ HAT
A2: MANTIK: Bölgeler, temsilciliğimizin OLDUĞU yere göre değil, İSTANBUL'un coğrafyasına göre kuruldu. Her hat coğrafi olarak bitişik ilçelerden oluşur — takipçi tek günde turlayabilsin. Mevcut yük (1-3-2-3 temsilcilik) dört bölgeye dengeli dağıldı.
A3: Bölge | B3: Bölge adı | C3: Yaka | D3: Takipçi | E3: İlçe | F3: Mevcut | G3: Kapsama | H3: Hattın karakteri | I3: Bu bölgenin 1 numaralı işi
A4: 1 | B4: HALİÇ HATTI | C4: AVRUPA | D4: BOŞ | E4: 10 | F4: 1 | G4: =IFERROR(F4/E4,0) -> 0.1 | H4: En yüksek cami, İHL ve üniversite yoğunluğu. YediHilal'in 'cami merkezli hareket' ilkesinin en verimli uygulanacağı hat. | I4: Bir TAKİPÇİ bul. Sonra Fatih ve Eyüpsultan'da koordinatör ara — İHL ve cami ağı en güçlü burada.
A5: 2 | B5: TRAKYA HATTI | C5: AVRUPA | D5: BOŞ | E5: 15 | F5: 3 | G5: =IFERROR(F5/E5,0) -> 0.2 | H5: İstanbul'un en kalabalık genç nüfusu burada. Mevcut 3 temsilcilik burada; büyüme potansiyeli en yüksek hat. | I5: Bir TAKİPÇİ bul. Sonra Güngören'i aç (Bağcılar-Bahçelievler'in tam ortasında, en kolay açılış).
A6: 3 | B6: BOĞAZ HATTI | C6: ANADOLU | D6: Nusret Onur Anlı | E6: 6 | F6: 2 | G6: =IFERROR(F6/E6,0) -> 0.33333333 | H6: Genel Merkez bu hatta (Üsküdar). Mevcut 2 temsilcilik de kritik durumda — önce kurtarma, sonra genişleme. | I6: Üsküdar ve Ümraniye'yi KURTAR. İkisi de kadro erimesinde. Genişleme sonra.
A7: 4 | B7: MARMARA HATTI | C7: ANADOLU | D7: Mehmet Menteş | E7: 8 | F7: 3 | G7: =IFERROR(F7/E7,0) -> 0.375 | H7: Teşkilatın en sağlam hattı (Kartal). Örnek uygulamalar buradan çıkarılıp diğer hatlara taşınacak. | I7: Pendik'e asil temsilci ata. Kartal'ın iyi uygulamalarını çıkar, diğer hatlara model yap.
B8: İSTANBUL TOPLAM | E8: =SUM(E4:E7) -> 39 | F8: =SUM(F4:F7) -> 9 | G8: =IFERROR(F8/E8,0) -> 0.23076923
A10: BÖLGE TAKİPÇİSİNİN GÖREV TANIMI (yazılı ver — sözle verilen görev tutmaz)
A11: # | B11: Görev | C11: Sıklık | D11: Çıktı
A12: 1 | B12: Bölgesindeki MEVCUT temsilcileri arar, durumunu sorar | C12: Haftada 1 | D12: Temsilcilik başına 1 satır durum notu
A13: 2 | B13: Bölgesindeki HEDEF ilçelerde yeni temas kurar (imam, öğretmen, genç) | C13: Haftada en az 1 temas | D13: Aday havuzuna giriş
A14: 3 | B14: Faaliyet raporlarının zamanında gelmesini sağlar | C14: Aylık | D14: Gelmezse Sekreterya'ya bildirir
A15: 4 | B15: Program ve kamplarda katılım sayısını toplar | C15: Program bazında | D15: Sekme 15'e giriş
A16: 5 | B16: Ayda en az 1 temsilcilik ziyaret eder | C16: Aylık | D16: Ziyaret formu (Sekme 12)
A17: 6 | B17: Bölge özetini Başkan'a verir | C17: Haftalık (Cuma) | D17: 5 satırlık bölge özeti
A18: 7 | B18: Pazartesi toplantısında bölgesini 1 dakikada sunar | C18: Haftalık | D18: Toplantı tutanağına işlenir
A19: 8 | B19: Karne aramalarını yapar veya destekler | C19: Aylık | D19: Karne dosyasına ham veri girişi
A21: EN KRİTİK BOŞLUK: BÖLGE 1 (Haliç, 10 ilçe) ve BÖLGE 2 (Trakya, 15 ilçe) takipçisiz. İstanbul'un 25 ilçesi bugün kimsenin sorumluluğunda değil — mevcut 4 temsilcilik (Kağıthane, Bağcılar, Bahçelievler, Esenler) dahil. Geçici çözüm: Serdar ve Burak'ı yarı zamanlı 'yoklama' seviyesinde ata. Kalıcı çözüm: Reis'ten 2 isim.

Sheet 8 Ilce Haritasi
A1: İSTANBUL TEŞKİLAT HARİTASI — 39 İLÇE / 4 HAT
B3: AVRUPA YAKASI · 25 İLÇE | I3: ANADOLU YAKASI · 14 İLÇE
B5: BÖLGE 1 — HALİÇ HATTI (10 ilçe · 1 temsilcilik) | H5: B O Ğ A Z İ Ç İ | I5: BÖLGE 3 — BOĞAZ HATTI (6 ilçe · 2 temsilcilik)
B6: Takipçi: BOŞ ⚠ ATANMADI | I6: Takipçi: Nusret Onur Anlı
B7: Fatih | D7: Eyüpsultan | F7: Gaziosmanpaşa | I7: Üsküdar (Kirazlıtepe) | K7: Ümraniye | M7: Sancaktepe
B8: Sultangazi | D8: Bayrampaşa | F8: Kağıthane | I8: Çekmeköy | K8: Ataşehir | M8: Beykoz
B9: Beyoğlu | D9: Şişli | F9: Sarıyer
B10: Beşiktaş | I10: BÖLGE 4 — MARMARA HATTI (8 ilçe · 3 temsilcilik)
I11: Takipçi: Mehmet Menteş
B12: BÖLGE 2 — TRAKYA HATTI (15 ilçe · 3 temsilcilik) | I12: Kadıköy | K12: Kartal | M12: Pendik
B13: Takipçi: BOŞ ⚠ ATANMADI | I13: Maltepe | K13: Sultanbeyli | M13: Tuzla
B14: Bağcılar | D14: Bahçelievler | F14: Esenler | I14: Şile | K14: Adalar
B15: Güngören | D15: Küçükçekmece | F15: Başakşehir
B16: Esenyurt | D16: Zeytinburnu | F16: Bakırköy
B17: Avcılar | D17: Beylikdüzü | F17: Büyükçekmece
B18: Arnavutköy | D18: Çatalca | F18: Silivri
B21: LEJANT
B22: BÖLGE 1 — HALİÇ HATTI | C22: Tarihî merkez, Haliç ve Boğaz'ın Avrupa yakası — Takipçi: BOŞ
B23: BÖLGE 2 — TRAKYA HATTI | C23: Avrupa yakasının batısı — iç batı ve dış batı — Takipçi: BOŞ
B24: BÖLGE 3 — BOĞAZ HATTI | C24: Anadolu yakasının kuzeyi, Boğaz ve çevresi — Takipçi: Nusret Onur Anlı
B25: BÖLGE 4 — MARMARA HATTI | C25: Anadolu yakasının Marmara sahili — Takipçi: Mehmet Menteş
B26: TEMSİLCİLİĞİMİZ VAR | C26: 9 ilçe — koyu yeşil. Bunları KORUYACAĞIZ.
B27: TEMSİLCİLİĞİMİZ YOK | C27: 30 ilçe — bölge rengi. Bunlar bölge takipçisinin GÖREVİDİR. Boş kutu = açık görev.
B29: BU HARİTA NE İŞE YARAR: Bunu yazdır, komisyon odasının duvarına as. Her yeni temsilcilik açıldığında o kutuyu koyu yeşile boya. Ekip, İstanbul'un ne kadarını kapladığını ve daha ne kadar yolu olduğunu tek bakışta görsün. BUGÜN: 9 yeşil, 30 boş. İstanbul'un %23'ündeyiz. · 1 YIL SONRA HEDEF: 11-13 yeşil. · 3 YIL SONRA: 25-30 yeşil.

Sheet 9 Ilce Envanteri
A1: İLÇE ENVANTERİ — İSTANBUL'UN 39 İLÇESİNİN TAMAMI
A2: # | B2: Bölge | C2: İLÇE | D2: Durum | E2: Temsilci | F2: Risk | G2: Öncelik | H2: Takipçi | I2: Durum notu / potansiyel | J2: Öncelikli aksiyon | K2: Ziyaret / temas tarihi
A3: 1 | B3: B1 HALİÇ HATTI | C3: Fatih | D3: HEDEF | F3: — | G3: 1 | H3: BOŞ | I3: Tarihî yarımada. İHL ve üniversite yoğunluğu en yüksek ilçe. Cami merkezli çalışma için en verimli zemin. | J3: Koordinatör arayışı — bkz. Sekme 10
A4: 2 | B4: B1 HALİÇ HATTI | C4: Eyüpsultan | D4: HEDEF | F4: — | G4: 1 | H4: BOŞ | I4: Cami merkezli çalışmanın sembol ilçesi. Genç nüfus yoğun. | J4: Koordinatör arayışı — bkz. Sekme 10
A5: 3 | B5: B1 HALİÇ HATTI | C5: Gaziosmanpaşa | D5: HEDEF | F5: — | G5: 1 | H5: BOŞ | I5: Yoğun genç nüfus, muhafazakâr doku. Öncelikli açılış adayı. | J5: Koordinatör arayışı — bkz. Sekme 10
A6: 4 | B6: B1 HALİÇ HATTI | C6: Sultangazi | D6: HEDEF | F6: — | G6: 1 | H6: BOŞ | I6: Genç nüfus çok yüksek. Kağıthane ekibi buradan isim çıkarabilir. | J6: Koordinatör arayışı — bkz. Sekme 10
A7: 5 | B7: B1 HALİÇ HATTI | C7: Bayrampaşa | D7: HEDEF | F7: — | G7: 1 | H7: BOŞ | I7: Merkezî konum, ulaşımı kolay. | J7: Koordinatör arayışı — bkz. Sekme 10
A8: 6 | B8: B1 HALİÇ HATTI | C8: Kağıthane | D8: MEVCUT | E8: Adem Abi | F8: Yüksek | G8: — | H8: BOŞ | I8: MEVCUT — Adem Abi. Kadro yaşlanmış, gençleşme şart. | J8: Gençleştirme planı; genç kadro kazanımı (mahalleleşme sonra)
A9: 7 | B9: B1 HALİÇ HATTI | C9: Beyoğlu | D9: HEDEF | F9: — | G9: 2 | H9: BOŞ | I9: Karma doku. Önce cami ve okul ağı kurulmalı. | J9: Koordinatör arayışı — bkz. Sekme 10
A10: 8 | B10: B1 HALİÇ HATTI | C10: Şişli | D10: HEDEF | F10: — | G10: 2 | H10: BOŞ | I10: Zor zemin. Üniversite üzerinden girilebilir. | J10: Koordinatör arayışı — bkz. Sekme 10
A11: 9 | B11: B1 HALİÇ HATTI | C11: Sarıyer | D11: HEDEF | F11: — | G11: 2 | H11: BOŞ | I11: Üniversite yoğunluğu (Boğaziçi, İTÜ). Üniversite birimi ile koordineli. | J11: Koordinatör arayışı — bkz. Sekme 10
A12: 10 | B12: B1 HALİÇ HATTI | C12: Beşiktaş | D12: HEDEF | F12: — | G12: 3 | H12: BOŞ | I12: En zor zemin. Şimdilik erteleme, üniversite çalışması ile sınırlı tut. | J12: Koordinatör arayışı — bkz. Sekme 10
A13: 11 | B13: B2 TRAKYA HATTI | C13: Bağcılar | D13: MEVCUT | F13: Düşük | G13: — | H13: BOŞ | I13: MEVCUT — genel olarak iyi. Eğitimci takviyesi teyit edilmeli. | J13: Eğitimci takviyesi teyit; Çağın Sancaktarı grubunu kur
A14: 12 | B14: B2 TRAKYA HATTI | C14: Bahçelievler | D14: MEVCUT | E14: Yusuf Hoca | F14: Orta | G14: — | H14: BOŞ | I14: MEVCUT — Yusuf Hoca. Okul merkezli aktif ekip, teşkilat düzenine entegre değil. | J14: Okul ekibi ile teşkilat ekibini ayrıştır; toplantı saatini uyarla
A15: 13 | B15: B2 TRAKYA HATTI | C15: Esenler | D15: MEVCUT | F15: Yüksek | G15: — | H15: BOŞ | I15: MEVCUT — durgun. Genç temsilci ve yeni kadro şart. | J15: Genç temsilci adayı; kurucu heyeti yeniden kur
A16: 14 | B16: B2 TRAKYA HATTI | C16: Güngören | D16: HEDEF | F16: — | G16: 1 | H16: BOŞ | I16: Bağcılar ve Bahçelievler'in tam ortasında. En kolay açılacak ilçe. | J16: Koordinatör arayışı — bkz. Sekme 10
A17: 15 | B17: B2 TRAKYA HATTI | C17: Küçükçekmece | D17: HEDEF | F17: — | G17: 1 | H17: BOŞ | I17: İstanbul'un en kalabalık ilçelerinden. Genç nüfus çok yüksek. | J17: Koordinatör arayışı — bkz. Sekme 10
A18: 16 | B18: B2 TRAKYA HATTI | C18: Başakşehir | D18: HEDEF | F18: — | G18: 1 | H18: BOŞ | I18: Yeni yerleşim, genç aile yoğunluğu. Cami ve okul altyapısı güçlü. | J18: Koordinatör arayışı — bkz. Sekme 10
A19: 17 | B19: B2 TRAKYA HATTI | C19: Esenyurt | D19: HEDEF | F19: — | G19: 1 | H19: BOŞ | I19: Devasa genç nüfus. Zor ama getirisi en yüksek ilçelerden. | J19: Koordinatör arayışı — bkz. Sekme 10
A20: 18 | B20: B2 TRAKYA HATTI | C20: Zeytinburnu | D20: HEDEF | F20: — | G20: 1 | H20: BOŞ | I20: Yoğun doku, İHL güçlü. | J20: Koordinatör arayışı — bkz. Sekme 10
A21: 19 | B21: B2 TRAKYA HATTI | C21: Bakırköy | D21: HEDEF | F21: — | G21: 2 | H21: BOŞ | I21: Karma doku. Okul üzerinden girilir. | J21: Koordinatör arayışı — bkz. Sekme 10
A22: 20 | B22: B2 TRAKYA HATTI | C22: Avcılar | D22: HEDEF | F22: — | G22: 2 | H22: BOŞ | I22: Üniversite (İstanbul Üniv. Avcılar) üzerinden girilebilir. | J22: Koordinatör arayışı — bkz. Sekme 10
A23: 21 | B23: B2 TRAKYA HATTI | C23: Beylikdüzü | D23: HEDEF | F23: — | G23: 2 | H23: BOŞ | I23: Yeni yerleşim, orta vadeli hedef. | J23: Koordinatör arayışı — bkz. Sekme 10
A24: 22 | B24: B2 TRAKYA HATTI | C24: Büyükçekmece | D24: HEDEF | F24: — | G24: 2 | H24: BOŞ | I24: Orta vadeli hedef. | J24: Koordinatör arayışı — bkz. Sekme 10
A25: 23 | B25: B2 TRAKYA HATTI | C25: Arnavutköy | D25: HEDEF | F25: — | G25: 2 | H25: BOŞ | I25: Muhafazakâr doku, potansiyel yüksek ama uzak. | J25: Koordinatör arayışı — bkz. Sekme 10
A26: 24 | B26: B2 TRAKYA HATTI | C26: Çatalca | D26: HEDEF | F26: — | G26: 3 | H26: BOŞ | I26: Uzak, düşük nüfus. Şimdilik erteleme. | J26: Koordinatör arayışı — bkz. Sekme 10
A27: 25 | B27: B2 TRAKYA HATTI | C27: Silivri | D27: HEDEF | F27: — | G27: 3 | H27: BOŞ | I27: Uzak, düşük öncelik. 3. yıl konusu. | J27: Koordinatör arayışı — bkz. Sekme 10
A28: 26 | B28: B3 BOĞAZ HATTI | C28: Üsküdar (Kirazlıtepe) | D28: MEVCUT | F28: KRİTİK | G28: — | H28: Nusret Onur Anlı | I28: MEVCUT — KRİTİK. Kadro eriyor, acil genç ekip ve genç temsilci gerek. Genel Merkez de Üsküdar'da. | J28: Eğitimci vasıflı genç isimler; genç temsilci adayı — ACİL
A29: 27 | B29: B3 BOĞAZ HATTI | C29: Ümraniye | D29: MEVCUT | E29: Ulvi Abi | F29: Yüksek | G29: — | H29: Nusret Onur Anlı | I29: MEVCUT — Ulvi Abi süreçleri takip edemiyor. Akif Kökalan üzerinden görev dağılımı. | J29: Akif Kökalan üzerinden yeni görev dağılımı; Ulvi Abi'ye onurlu konum
A30: 28 | B30: B3 BOĞAZ HATTI | C30: Sancaktepe | D30: HEDEF | F30: — | G30: 1 | H30: Nusret Onur Anlı | I30: Ümraniye ekibinden isim çıkabilir. Genç nüfus yoğun. | J30: Koordinatör arayışı — bkz. Sekme 10
A31: 29 | B31: B3 BOĞAZ HATTI | C31: Çekmeköy | D31: HEDEF | F31: — | G31: 1 | H31: Nusret Onur Anlı | I31: Muhafazakâr doku, yeni yerleşim. Yüksek potansiyel. | J31: Koordinatör arayışı — bkz. Sekme 10
A32: 30 | B32: B3 BOĞAZ HATTI | C32: Ataşehir | D32: HEDEF | F32: — | G32: 1 | H32: Nusret Onur Anlı | I32: Merkezî, ulaşımı kolay. Orta vadede açılabilir. | J32: Koordinatör arayışı — bkz. Sekme 10
A33: 31 | B33: B3 BOĞAZ HATTI | C33: Beykoz | D33: HEDEF | F33: — | G33: 2 | H33: Nusret Onur Anlı | I33: Dağınık yerleşim, ulaşım zor. Cami ağı üzerinden girilir. | J33: Koordinatör arayışı — bkz. Sekme 10
A34: 32 | B34: B4 MARMARA HATTI | C34: Kadıköy | D34: MEVCUT | F34: Düşük | G34: — | H34: Mehmet Menteş | I34: MEVCUT — başkan ve ekip uyumlu, faaliyet hacmi düşük. Mahalleleşme pilotu adayı. | J34: Aylık faaliyet hedefi; mahalleleşme pilotu adayı
A35: 33 | B35: B4 MARMARA HATTI | C35: Kartal | D35: MEVCUT | F35: Düşük | G35: — | H35: Mehmet Menteş | I35: MEVCUT — ÖRNEK TEMSİLCİLİK. Yaz okulu düzenli, ekip sağlam. Model olarak sunulmalı. | J35: İyi uygulamalarını çıkar, diğer hatlara model sun
A36: 34 | B36: B4 MARMARA HATTI | C36: Pendik | D36: MEVCUT | E36: Osman Nuri (vekâleten) | F36: KRİTİK | G36: — | H36: Mehmet Menteş | I36: MEVCUT — KRİTİK. Asil temsilci yok, vekâlet belirsiz, ekip dağılma riski. | J36: Mehmet Emin Bey ile görüş, sonra asil temsilci ata — en geç 30 gün
A37: 35 | B37: B4 MARMARA HATTI | C37: Maltepe | D37: HEDEF | F37: — | G37: 1 | H37: Mehmet Menteş | I37: Kartal ve Kadıköy'ün arasında. İki ekipten de isim çıkabilir. | J37: Koordinatör arayışı — bkz. Sekme 10
A38: 36 | B38: B4 MARMARA HATTI | C38: Sultanbeyli | D38: HEDEF | F38: — | G38: 1 | H38: Mehmet Menteş | I38: Muhafazakâr doku, genç nüfus yoğun. Pendik toparlanınca sıra bunda. | J38: Koordinatör arayışı — bkz. Sekme 10
A39: 37 | B39: B4 MARMARA HATTI | C39: Tuzla | D39: HEDEF | F39: — | G39: 2 | H39: Mehmet Menteş | I39: Üniversite (Sabancı) ve sanayi. Orta vadeli. | J39: Koordinatör arayışı — bkz. Sekme 10
A40: 38 | B40: B4 MARMARA HATTI | C40: Şile | D40: HEDEF | F40: — | G40: 3 | H40: Mehmet Menteş | I40: Uzak, düşük nüfus. Erteleme. | J40: Koordinatör arayışı — bkz. Sekme 10
...

Sheet 10 Yeni Teskilat Hatti
A1: YENİ TEŞKİLAT HATTI — 30 HEDEF İLÇE, 5 AŞAMALI AÇILIŞ HUNİSİ
A2: Temsilciliğimiz OLMAYAN 30 ilçenin tamamı burada. Her ilçe 5 aşamalı huniden geçer ve hangi aşamada olduğu her an bellidir. Öncelik 1'ler üstte — enerjini oraya yığ.
A3: # | B3: Bölge | C3: HEDEF İLÇE | D3: Önc. | E3: Bulunduğu aşama | F3: Koordinatör adayı | G3: Kurucu heyet (/9) | H3: Sonraki adım | I3: Termin | J3: Sorumlu
A4: 1 | B4: B1 HALİÇ HATTI | C4: Fatih | D4: 1 | E4: 1 - Koordinatör arayışı | G4: 0 | H4: Tarihî yarımada. İHL ve üniversite yoğunluğu en yüksek ilçe. Cami merkezli çalışma için en verimli zemin. | J4: BOŞ
A5: 2 | B5: B1 HALİÇ HATTI | C5: Eyüpsultan | D5: 1 | E5: 1 - Koordinatör arayışı | G5: 0 | H5: Cami merkezli çalışmanın sembol ilçesi. Genç nüfus yoğun. | J5: BOŞ
A6: 3 | B6: B1 HALİÇ HATTI | C6: Gaziosmanpaşa | D6: 1 | E6: 1 - Koordinatör arayışı | G6: 0 | H6: Yoğun genç nüfus, muhafazakâr doku. Öncelikli açılış adayı. | J6: BOŞ
A7: 4 | B7: B1 HALİÇ HATTI | C7: Sultangazi | D7: 1 | E7: 1 - Koordinatör arayışı | G7: 0 | H7: Genç nüfus çok yüksek. Kağıthane ekibi buradan isim çıkarabilir. | J7: BOŞ
A8: 5 | B8: B1 HALİÇ HATTI | C8: Bayrampaşa | D8: 1 | E8: 1 - Koordinatör arayışı | G8: 0 | H8: Merkezî konum, ulaşımı kolay. | J8: BOŞ
A9: 6 | B9: B2 TRAKYA HATTI | C9: Güngören | D9: 1 | E9: 1 - Koordinatör arayışı | G9: 0 | H9: Bağcılar ve Bahçelievler'in tam ortasında. En kolay açılacak ilçe. | J9: BOŞ
A10: 7 | B10: B2 TRAKYA HATTI | C10: Küçükçekmece | D10: 1 | E10: 1 - Koordinatör arayışı | G10: 0 | H10: İstanbul'un en kalabalık ilçelerinden. Genç nüfus çok yüksek. | J10: BOŞ
A11: 8 | B11: B2 TRAKYA HATTI | C11: Başakşehir | D11: 1 | E11: 1 - Koordinatör arayışı | G11: 0 | H11: Yeni yerleşim, genç aile yoğunluğu. Cami ve okul altyapısı güçlü. | J11: BOŞ
A12: 9 | B12: B2 TRAKYA HATTI | C12: Esenyurt | D12: 1 | E12: 1 - Koordinatör arayışı | G12: 0 | H12: Devasa genç nüfus. Zor ama getirisi en yüksek ilçelerden. | J12: BOŞ
A13: 10 | B13: B2 TRAKYA HATTI | C13: Zeytinburnu | D13: 1 | E13: 1 - Koordinatör arayışı | G13: 0 | H13: Yoğun doku, İHL güçlü. | J13: BOŞ
A14: 11 | B14: B3 BOĞAZ HATTI | C14: Sancaktepe | D14: 1 | E14: 1 - Koordinatör arayışı | G14: 0 | H14: Ümraniye ekibinden isim çıkabilir. Genç nüfus yoğun. | J14: Nusret Onur Anlı
A15: 12 | B15: B3 BOĞAZ HATTI | C15: Çekmeköy | D15: 1 | E15: 1 - Koordinatör arayışı | G15: 0 | H15: Muhafazakâr doku, yeni yerleşim. Yüksek potansiyel. | J15: Nusret Onur Anlı
... A33: 30 | B33: B4 MARMARA HATTI | C33: Adalar | D33: 3 | E33: 1 - Koordinatör arayışı | G33: 0 | H33: Çok küçük nüfus. Teşkilat açılması gerekmez, program bazlı temas yeterli. | J33: Mehmet Menteş
B35: Toplam hedef ilçe | C35: =COUNTA(C4:C33) -> 30
B36: Aşama 5'e (açılışa) gelen | C36: =COUNTIF(E4:E33,"5 - Açılış") -> 0
B37: Koordinatörü bulunmuş ilçe | C37: =COUNTIF(F4:F33,"<>") -> 0
A39: 5 AŞAMALI HUNİ — HER İLÇE BUNDAN GEÇER
A40: Aşama | B40: Adı | C40: Ne yapılır | D40: Bitiş şartı | E40: Süre | F40: Sorumlu
A41: 1 | B41: Koordinatör arayışı | C41: İlçede bir isim bul. Kaynaklar: imamlar, İHL öğretmenleri, komşu temsilciliğin oradan gelen üyeleri, gönüllü formu, üniversite öğrencileri, STK temasları, kamplarda parlayan gençler. | D41: İlçede güvenilir 1 isim + Aday Havuzu'nda 70+ puan | E41: 1-3 ay | F41: Bölge takipçisi + Yeni Teşkilat
A42: 2 | B42: Tanışma toplantısı | C42: Koordinatör, ilçedeki muhtemel isimlerle ilk toplantıyı kurar. YediHilal anlatılır. Katılanlardan YENİ İSİM TAVSİYESİ alınır, onlar da bir sonrakine çağrılır. | D42: En az 2 toplantı, katılım 6+ kişi | E42: 1-2 ay | F42: Koordinatör
A43: 3 | B43: Kurucu heyet | C43: 9 kişilik kurucu heyet + istişare heyeti. İçinde öğretmen/imam/avukat/mali müşavir ve liseli-üniversiteli genç bulunmalı (Rehber şartı). | D43: 9 kişi tamam + görev dağılımı | E43: 2-3 ay | F43: Koordinatör + Başkan
A44: 4 | B44: Mekân + mali taahhüt | C44: Rehberdeki mekân kriterleri (düzayak giriş, camiye yakın, ayrı odalar) + aylık kiranın 2 katı gelir taahhüdü. | D44: Mekân + aidat taahhüdü | E44: 1-3 ay | F44: Koordinatör
A45: 5 | B45: Açılış | C45: Genel Merkez Yönetim Kurulu'na sunulur; onay çıkarsa temsilcilik açılır. Haritada kutu KOYU YEŞİL olur. | D45: GM onayı + resmî açılış | E45: 1 ay | F45: Başkan + GM Teşkilat
A47: ALTIN KURAL: Aşama 3 (9 kişilik kurucu heyet) tamamlanmadan hiçbir ilçeyi 'açıldı' sayma ve Reis'e sayı olarak sunma. Rehber bunu açıkça yazıyor. Erken verilen sayı, 6 ay sonra dağılan bir temsilcilik olarak önüne gelir. İNSAN NEREDEN BULUNUR: 1) Camiler ve imamlar (rehberin 'cami merkezli hareket' ilkesi tam bunun için) · 2) İmam-Hatip öğretmenleri (öncelikli kitle) · 3) Komşu temsilcilikteki, hedef ilçede oturan üyeler — EN HIZLI YOL BU · 4) Üniversite öğrencileri · 5) Gönüllü formu · 6) STK temasların (Sekme 16) · 7) Kamplarda ve salon programlarında parlayan gençler.

Sheet 11 Aday Havuzu
A1: ADAY HAVUZU — «NİTELİKLİ İNSAN» DEĞERLENDİRME VE GÖREV TEVDİİ
A2: Kriterler uydurma değil: 6'sı YediHilal'in kendi sunumundaki «Nitelikli İnsan» maddeleri, 4'ü Teşkilatlanma Rehberi'ndeki «Görevli/Yönetici Kriterleri». Her kriter 0-5 puanlanır; toplam ve önerilen görev otomatik çıkar.
H3: Sorumluluk sahibi (verilen işi bitirir) | I3: Eğitimli / fikrî donanım | J3: İşini bilen (mesleki yetkinlik) | K3: Şuurlu, dert sahibi | L3: İnsanlarla iyi geçinen, çevresinde saygın | M3: Fedakârlık (zaman ayırabiliyor) | N3: Dinî hassasiyet, temel ibadetlerde amel | O3: Siyasi aşırılık ve meşrep taassubu yok | P3: Başka gençlik çalışmasında aktif görevi yok | Q3: Hukuki/ticari/ahlaki yıpranmışlık yok
A4: # | B4: Ad Soyad | C4: İlçe (39'dan) | D4: Yaş | E4: Meslek | F4: Nereden / tavsiye eden | G4: İlk görüşen | H4: K1 | I4: K2 | J4: K3 | K4: K4 | L4: K5 | M4: K6 | N4: K7 | O4: K8 | P4: K9 | Q4: K10 | R4: PUAN | S4: ÖNERİLEN GÖREV | T4: Durum
G5: AĞIRLIK → | H5: 14 | I5: 10 | J5: 10 | K5: 14 | L5: 10 | M5: 14 | N5: 10 | O5: 6 | P5: 6 | Q5: 6 | R5: =SUM(H5:Q5) -> 100 | S5: ← 100 olmalı
A6: 1 | H6: 0 | I6: 0 | J6: 0 | K6: 0 | L6: 0 | M6: 0 | N6: 0 | O6: 0 | P6: 0 | Q6: 0 | R6: =SUMPRODUCT($H$5:$Q$5,H6:Q6)/5 -> 0 | S6: =IF(SUM(H6:Q6)=0,"—",IF(R6>=85,"Temsilci / Birim Başkanı adayı",IF(R6>=70,"Aktif görevli / birim üyesi",IF(R6>=50,"Gözlem — programlara davet et","Henüz görev verme")))) -> —
A7: 2 | H7: 0 | I7: 0 | J7: 0 | K7: 0 | L7: 0 | M7: 0 | N7: 0 | O7: 0 | P7: 0 | Q7: 0 | R7: =SUMPRODUCT($H$5:$Q$5,H7:Q7)/5 -> 0 | S7: =IF(SUM(H7:Q7)=0,"—",IF(R7>=85,"Temsilci / Birim Başkanı adayı",IF(R7>=70,"Aktif görevli / birim üyesi",IF(R7>=50,"Gözlem — programlara davet et","Henüz görev verme")))) -> —
A8: 3 | H8: 0 | I8: 0 | J8: 0 | K8: 0 | L8: 0 | M8: 0 | N8: 0 | O8: 0 | P8: 0 | Q8: 0 | R8: =SUMPRODUCT($H$5:$Q$5,H8:Q8)/5 -> 0 | S8: =IF(SUM(H8:Q8)=0,"—",IF(R8>=85,"Temsilci / Birim Başkanı adayı",IF(R8>=70,"Aktif görevli / birim üyesi",IF(R8>=50,"Gözlem — programlara davet et","Henüz görev verme")))) -> —
A9: 4 | H9: 0 | I9: 0 | J9: 0 | K9: 0 | L9: 0 | M9: 0 | N9: 0 | O9: 0 | P9: 0 | Q9: 0 | R9: =SUMPRODUCT($H$5:$Q$5,H9:Q9)/5 -> 0 | S9: =IF(SUM(H9:Q9)=0,"—",IF(R9>=85,"Temsilci / Birim Başkanı adayı",IF(R9>=70,"Aktif görevli / birim üyesi",IF(R9>=50,"Gözlem — programlara davet et","Henüz görev verme")))) -> —
A10: 5 | H10: 0 | I10: 0 | J10: 0 | K10: 0 | L10: 0 | M10: 0 | N10: 0 | O10: 0 | P10: 0 | Q10: 0 | R10: =SUMPRODUCT($H$5:$Q$5,H10:Q10)/5 -> 0 | S10: =IF(SUM(H10:Q10)=0,"—",IF(R10>=85,"Temsilci / Birim Başkanı adayı",IF(R10>=70,"Aktif görevli / birim üyesi",IF(R10>=50,"Gözlem — programlara davet et","Henüz görev verme")))) -> —
A11: 6 | H11: 0 | I11: 0 | J11: 0 | K11: 0 | L11: 0 | M11: 0 | N11: 0 | O11: 0 | P11: 0 | Q11: 0 | R11: =SUMPRODUCT($H$5:$Q$5,H11:Q11)/5 -> 0 | S11: =IF(SUM(H11:Q11)=0,"—",IF(R11>=85,"Temsilci / Birim Başkanı adayı",IF(R11>=70,"Aktif görevli / birim üyesi",IF(R11>=50,"Gözlem — programlara davet et","Henüz görev verme")))) -> —
A12: 7 | H12: 0 | I12: 0 | J12: 0 | K12: 0 | L12: 0 | M12: 0 | N12: 0 | O12: 0 | P12: 0 | Q12: 0 | R12: =SUMPRODUCT($H$5:$Q$5,H12:Q12)/5 -> 0 | S12: =IF(SUM(H12:Q12)=0,"—",IF(R12>=85,"Temsilci / Birim Başkanı adayı",IF(R12>=70,"Aktif görevli / birim üyesi",IF(R12>=50,"Gözlem — programlara davet et","Henüz görev verme")))) -> —
A13: 8 | H13: 0 | I13: 0 | J13: 0 | K13: 0 | L13: 0 | M13: 0 | N13: 0 | O13: 0 | P13: 0 | Q13: 0 | R13: =SUMPRODUCT($H$5:$Q$5,H13:Q13)/5 -> 0 | S13: =IF(SUM(H13:Q13)=0,"—",IF(R13>=85,"Temsilci / Birim Başkanı adayı",IF(R13>=70,"Aktif görevli / birim üyesi",IF(R13>=50,"Gözlem — programlara davet et","Henüz görev verme")))) -> —
A14: 9 | H14: 0 | I14: 0 | J14: 0 | K14: 0 | L14: 0 | M14: 0 | N14: 0 | O14: 0 | P14: 0 | Q14: 0 | R14: =SUMPRODUCT($H$5:$Q$5,H14:Q14)/5 -> 0 | S14: =IF(SUM(H14:Q14)=0,"—",IF(R14>=85,"Temsilci / Birim Başkanı adayı",IF(R14>=70,"Aktif görevli / birim üyesi",IF(R14>=50,"Gözlem — programlara davet et","Henüz görev verme")))) -> —
A15: 10 | H15: 0 | I15: 0 | J15: 0 | K15: 0 | L15: 0 | M15: 0 | N15: 0 | O15: 0 | P15: 0 | Q15: 0 | R15: =SUMPRODUCT($H$5:$Q$5,H15:Q15)/5 -> 0 | S15: =IF(SUM(H15:Q15)=0,"—",IF(R15>=85,"Temsilci / Birim Başkanı adayı",IF(R15>=70,"Aktif görevli / birim üyesi",IF(R15>=50,"Gözlem — programlara davet et","Henüz görev verme")))) -> —
A16: 11 | H16: 0 | I16: 0 | J16: 0 | K16: 0 | L16: 0 | M16: 0 | N16: 0 | O16: 0 | P16: 0 | Q16: 0 | R16: =SUMPRODUCT($H$5:$Q$5,H16:Q16)/5 -> 0 | S16: =IF(SUM(H16:Q16)=0,"—",IF(R16>=85,"Temsilci / Birim Başkanı adayı",IF(R16>=70,"Aktif görevli / birim üyesi",IF(R16>=50,"Gözlem — programlara davet et","Henüz görev verme")))) -> —
A17: 12 | H17: 0 | I17: 0 | J17: 0 | K17: 0 | L17: 0 | M17: 0 | N17: 0 | O17: 0 | P17: 0 | Q17: 0 | R17: =SUMPRODUCT($H$5:$Q$5,H17:Q17)/5 -> 0 | S17: =IF(SUM(H17:Q17)=0,"—",IF(R17>=85,"Temsilci / Birim Başkanı adayı",IF(R17>=70,"Aktif görevli / birim üyesi",IF(R17>=50,"Gözlem — programlara davet et","Henüz görev verme")))) -> —
... A25: 20 | H25: 0 | I25: 0 | J25: 0 | K25: 0 | L25: 0 | M25: 0 | N25: 0 | O25: 0 | P25: 0 | Q25: 0 | R25: =SUMPRODUCT($H$5:$Q$5,H25:Q25)/5 -> 0 | S25: =IF(SUM(H25:Q25)=0,"—",IF(R25>=85,"Temsilci / Birim Başkanı adayı",IF(R25>=70,"Aktif görevli / birim üyesi",IF(R25>=50,"Gözlem — programlara davet et","Henüz görev verme")))) -> —
B27: Havuzdaki kişi | F27: =COUNTA(B6:B25) -> 0
B28: Temsilci adayı (85+) | F28: =COUNTIF(R6:R25,">=85") -> 0
B29: Aktif görevli adayı (70-84) | F29: =COUNTIFS(R6:R25,">=70",R6:R25,"<85") -> 0
B30: Gözlemde (50-69) | F30: =COUNTIFS(R6:R25,">=50",R6:R25,"<70") -> 0
A32: KULLANIM: Cumartesi dernek gününde tanıştığın her ismi aynı akşam buraya gir. Puanlamayı TEK BAŞINA yapma — Oğuzhan'la birlikte yap. İki kişinin ortak kanaati, tek kişinin izleniminden daima daha isabetlidir. İLÇE SÜTUNU ÖNEMLİ: Adayın hangi ilçede oturduğunu mutlaka yaz. 30 hedef ilçenin koordinatörleri bu havuzdan çıkacak. Bir aday Güngören'de oturuyorsa, o Güngören'in koordinatör adayıdır.

Sheet 12 Ziyaret Formu
A1: TEMSİLCİLİK ZİYARET STANDART FORMU
B2: Her ziyarette bir kopyası doldurulur → Sekreterya'ya teslim → o ayın karnesine veri olur.
A4: A) ZİYARET BİLGİLERİ
B5: Temsilcilik
B6: Bölge (hangi hat)
B7: Ziyaret tarihi
B8: Ziyaret eden
B9: Katılan YK üyesi
B10: Görüşülen kişiler
B11: Süre
A13: B) YERİNDE KONTROL LİSTESİ
A14: # | B14: Kontrol maddesi | C14: Durum (Var/Kısmen/Yok) | D14: Not
A15: 1 | B15: Yönetim Kurulu kaç kişi? Rehberdeki birimlerin kaçı dolu?
A16: 2 | B16: Haftalık YK toplantısı düzenli mi? Gün ve saat sabit mi?
A17: 3 | B17: Toplantı tutanağı tutuluyor mu? Son 4 tutanak görüldü mü?
A18: 4 | B18: Ortaokul birimi + Çağın Sancaktarı grubu (min. 10 kişi) var mı?
A19: 5 | B19: Lise birimi + Çağın Sancaktarı grubu (min. 10 kişi) var mı?
A20: 6 | B20: Haftalık halka açık sohbet var mı? Ortalama kaç kişi?
A21: 7 | B21: Cami merkezli program yapılıyor mu?
A22: 8 | B22: «Yatsıya Kadar» programı yapılıyor mu? (karnede 10 puan!)
A23: 9 | B23: Sabah namazı buluşması yapılıyor mu? (karnede 10 puan!)
A24: 10 | B24: Mekân: ayrı odalar, düzayak giriş, camiye yakınlık
A25: 11 | B25: Mali sistem: aidat toplanıyor mu? Gelir tasnifi yapılıyor mu?
A26: 12 | B26: Sosyal medya kurumsal kimliğe uygun mu? («YediHilal» yazımı doğru mu?)
... A33: 19 | B33: Bu temsilcilikten çıkabilecek 2 yeni isim var mı? → Aday Havuzu'na yaz
A35: C) ZİYARET SONUCU
B36: Genel izlenim (1-5)
B37: Öne çıkan güçlü yön
B38: En kritik 1 sorun
B39: Alınan kararlar
B40: Komisyondan beklenen destek
B41: Kadro/temsilci değişikliği gerekiyor mu? (+gerekçe)
B42: Bir sonraki kontrol tarihi
A44: ZİYARET ADABI: Ziyaret teftiş değil, destek görüşmesidir. Formu masaya koyup madde madde sorma — sohbet içinde öğren, formu sonra doldur. EN İYİ ZAMAN: CUMARTESİ SABAHI. Çağın Sancaktarı müfredatı cumartesi işleniyor (kahle vaktinden öğle namazına). O saatte gidersen ekibi, öğrencileri ve işleyişi aynı anda görürsün.

Sheet 13 Haftalik Ritim
A1: HAFTALIK ÇALIŞMA RİTMİ VE YILLIK KAPASİTE
A2: Teşkilat işi boş vakitte yapılmaz. Takvime yazılmayan iş yapılmamıştır (sunum: Zaman Yönetimi → Plan, Ertelememek, Sistemli Çalışma).
A3: Gün | B3: Saat | C3: Ne yapılır | D3: Nerede | E3: Kim | F3: Neden burada
A4: Pazartesi | B4: 21:00 – 23:00 | C4: KOMİSYON TOPLANTISI. Gündemli, tutanaklı. İlk gündem daima: geçen haftanın kararlarının takibi. | D4: İl dernek merkezi | E4: Tüm komisyon | F4: Mevcut düzen korunuyor.
A5: Salı – Çarşamba | B5: Mesai dışı | C5: BÖLGE TURU. Her takipçi kendi bölgesindeki mevcut temsilcileri arar + 1 hedef ilçede temas kurar. | D5: Telefon | E5: 4 bölge takipçisi | F5: Sen aramazsın — sistem arar. Delege etmezsen 39 ilçe altında ezilirsin.
A6: Perşembe | B6: 14:00 – 18:00 | C6: SAHA YARIM GÜNÜ. İşten çık: ziyaret, görüşme, telefon trafiği, aday görüşmeleri. | D6: Sahada | E6: Başkan + ziyaret ekibi | F6: Kendi ifadenle: yarım günü derneğe ayırıp telefon trafiğiyle çalışmak.
A7: Perşembe | B7: 18:00 – 20:00 | C7: İkinci haftalık toplantı. Saha çıktısı buraya taşınır. | D7: İl dernek merkezi | E7: Başkan + ilgili birim | F7: Haftada 2 toplantı zaten var; ikincisi sahadan dönüşe bağlandı.
A8: Cuma | B8: Kısa | C8: REİS'E HAFTALIK ÖZET: yapılan / yapılmayan / engel / karar / rakam. | D8: Mesaj | E8: Başkan | F8: Yöneticiyle ilişki: ön hazırlık ve düzenli bilgilendirme.
A9: CUMARTESİ | B9: 09:00 – 13:00 | C9: TEMSİLCİLİK ZİYARETİ (ayda 2 cumartesi). Çağın Sancaktarı ders saati. | D9: Temsilciliklerde | E9: Başkan + Ziyaret Birimi + 1 YK üyesi | F9: Ziyaretin en verimli saati. Boş binaya gitmek ziyaret sayılmaz.
A10: CUMARTESİ | B10: 14:00 – 18:00 | C10: DERNEK GÜNÜ. Gelen-giden, aday görüşmeleri, gönüllü formu adayları, evrak-arşiv. | D10: İl dernek merkezi | E10: Başkan + Oğuzhan | F10: Kendi ifadenle: cumartesiyi derneğe bağışlayıp sabahtan akşama orada olmak.
A11: CUMARTESİ | B11: Akşam | C11: O gün tanıştığın isimleri AYNI AKŞAM Aday Havuzu'na gir. | D11: Ev | E11: Başkan | F11: İzlenim 24 saatte solar. Aynı gün yazılmayan isim kaybolur.
A14: YILLIK KAPASİTE HESABI
A15: Kalem | B15: Değer | C15: Birim | D15: Not
A16: Haftalık dernek saati | B16: 15 | C16: saat/hafta | D16: Pazartesi 2 + Perşembe 6 + Cumartesi 8 ≈ 15-16. Mavi hücre — kendine göre değiştir.
A17: Yılda çalışılan hafta | B17: 44 | C17: hafta | D17: 8 hafta izin/kamp/tatil düşülmüş
A18: YILLIK TOPLAM KAPASİTE | B18: =B16*B17 -> 660 | C18: saat/yıl | D18: Senin gerçek bütçen. Her yeni iş buradan düşer.
A19: Bir temsilcilik ziyareti (yol dahil) | B19: 4 | C19: saat | D19: Ortalama
A20: Ayda kaç ziyaret? | B20: 3 | C20: ziyaret/ay | D20: 2 cumartesi × 1-2 ziyaret
A21: YILLIK ZİYARET KAPASİTESİ | B21: =B20*11 -> 33 | C21: ziyaret/yıl | D21: 11 ay. 9 temsilcilik → her birine 3-4 ziyaret düşer.
A22: Bir aday görüşmesi | B22: 1.5 | C22: saat | D22: Cumartesi öğleden sonra
A23: Yılda kaç aday görüşmesi? | B23: 60 | C23: görüşme/yıl | D23: 40 cumartesi × 1,5 görüşme
A25: KAPASİTE GERÇEĞİ: Haftada ~15 saatle 39 ilçelik bir şehri tek başına yönetemezsin. Bu tablo, Reis'e 'hayır' demeden sınırını göstermenin en nazik yoludur: «Reisim, elimdeki bütçe bu. Bölge takipçilerim olmadan bu bütçe 9 ilçeye ancak yeter.» Sunumun kendi ifadesiyle: İş–Okul–Vakıf–Aile Dengesi.

Sheet 14 Yillik Takvim
A1: YILLIK TEŞKİLAT TAKVİMİ — TEMMUZ 2026 / HAZİRAN 2027
A2: Ay | B2: Rutin (her ay) | C2: Büyük program | D2: Bu ayın teşkilat odağı | E2: Hatırlatma | F2: Katılım hedefi | G2: Durum
A3: Temmuz 26 | B3: Temsilciler toplantısı · Faaliyet raporu · Karne | C3: ÇADIR KAMPI | D3: Devir + 4 bölge yapısının ilanı + takipçi ataması | E3: Kamp öncesi tüm temsilcileri ara, taahhüt al
A4: Ağustos 26 | B4: Temsilciler toplantısı · Faaliyet raporu · Karne | C4: — | D4: Kritik temsilcilik ziyaretleri (Pendik, Üsküdar, Kağıthane, Ümraniye) | E4: İlk karne — deneme ayı olarak duyur
A5: Eylül 26 | B5: Temsilciler toplantısı · Faaliyet raporu · Karne | C5: Okul açılışı | D5: Okul birimleri + Öncelik 1 ilçelerde koordinatör arayışı başlar | E5: Çağın Sancaktarı EKİM'de başlıyor — gruplar eylülde hazır olmalı
A6: Ekim 26 | B6: Temsilciler toplantısı · Faaliyet raporu · Karne | C6: İL TEŞKİLAT KAMPI | D6: Dönem değerlendirme + Kasım-Aralık planlaması | E6: Çağın Sancaktarı müfredatı başladı — takibe al
A7: Kasım 26 | B7: Temsilciler toplantısı · Faaliyet raporu · Karne | C7: Salon programı | D7: Yeni teşkilat hattı: ilk 2-3 hedef ilçede tanışma toplantıları | E7: Aday havuzu 20 kişiyi geçmeli
A8: Aralık 26 | B8: Temsilciler toplantısı · Faaliyet raporu · Karne | C8: — | D8: Yıl sonu değerlendirme + karne ödülleri + kapsama raporu | E8: Reis'e 6 aylık dönem raporu
A9: Ocak 27 | B9: Temsilciler toplantısı · Faaliyet raporu · Karne | C9: KIŞ KAMPI | D9: Dönemlik planlama kampı | E9: Yarıyıl tatili — gençlik programları yoğunlaşır
A10: Şubat 27 | B10: Temsilciler toplantısı · Faaliyet raporu · Karne | C10: — | D10: Yeni teşkilat hattı: kurucu heyet oluşturma (Aşama 3) | E10: Çağın Sancaktarı devam ediyor
A11: Mart 27 | B11: Temsilciler toplantısı · Faaliyet raporu · Karne | C11: Salon programı | D11: Mekân + mali taahhüt aşaması (Aşama 4) | E11: Ramazan yaklaşıyor — itikâf kampı planı
A12: Nisan 27 | B12: Temsilciler toplantısı · Faaliyet raporu · Karne | C12: RAMAZAN / İtikâf | D12: Ramazan programları — yeni isim kazanımının en verimli ayı | E12: Ramazan'da tanışılan isimleri havuza yaz
A13: Mayıs 27 | B13: Temsilciler toplantısı · Faaliyet raporu · Karne | C13: — | D13: Çağın Sancaktarı kapanışı + ilk yeni temsilcilik açılış dosyaları | E13: Sınav dönemi — okul ekipleri yavaşlar, normal karşıla
A14: Haziran 27 | B14: Temsilciler toplantısı · Faaliyet raporu · Karne | C14: Yaz okulu | D14: Yıl sonu değerlendirme + 2. yıl (genişleme) planı | E14: Açılış dosyaları GM'ye sunulur
A16: PROGRAM ÖNCESİ RUTİN (her büyük program için aynı): T-4 hafta: temsilcilere duyuru + hedef kota · T-3: bölge takipçileri taahhüt toplar · T-2: kayıt listesi Sekme 15'e girer · T-1: eksik kalanlar ARANIR · Program günü: yoklama · T+1: kimler öne çıktı? → Aday Havuzu'na yaz.

Sheet 15 Program Katilim
A1: PROGRAM VE KAMP KATILIM TAKİBİ
A2: Hedefler MASADA belirlenmez — bölge takipçisi temsilciden TAAHHÜT alır, o rakam hedef olur.
A4: # | B4: Temsilcilik | C4: Bölge | D4: Temmuz Çadır Kampı HEDEF | E4: Temmuz Çadır Kampı KATILAN | F4: İl Teşkilat Kampı HEDEF | G4: İl Teşkilat Kampı KATILAN | H4: Salon Programı HEDEF | I4: Salon Programı KATILAN | J4: Kış Kampı HEDEF | K4: Kış Kampı KATILAN | L4: Toplam hedef | M4: Toplam katılan | N4: Gerçekleşme %
A5: 1 | B5: Kağıthane | C5: B1 HALİÇ HATTI | D5: 0 | E5: 0 | F5: 0 | G5: 0 | H5: 0 | I5: 0 | J5: 0 | K5: 0 | L5: =D5+F5+H5+J5 -> 0 | M5: =E5+G5+I5+K5 -> 0 | N5: =IFERROR(M5/L5,0) -> 0
A6: 2 | B6: Bağcılar | C6: B2 TRAKYA HATTI | D6: 0 | E6: 0 | F6: 0 | G6: 0 | H6: 0 | I6: 0 | J6: 0 | K6: 0 | L6: =D6+F6+H6+J6 -> 0 | M6: =E6+G6+I6+K6 -> 0 | N6: =IFERROR(M6/L6,0) -> 0
A7: 3 | B7: Bahçelievler | C7: B2 TRAKYA HATTI | D7: 0 | E7: 0 | F7: 0 | G7: 0 | H7: 0 | I7: 0 | J7: 0 | K7: 0 | L7: =D7+F7+H7+J7 -> 0 | M7: =E7+G7+I7+K7 -> 0 | N7: =IFERROR(M7/L7,0) -> 0
A8: 4 | B8: Esenler | C8: B2 TRAKYA HATTI | D8: 0 | E8: 0 | F8: 0 | G8: 0 | H8: 0 | I8: 0 | J8: 0 | K8: 0 | L8: =D8+F8+H8+J8 -> 0 | M8: =E8+G8+I8+K8 -> 0 | N8: =IFERROR(M8/L8,0) -> 0
A9: 5 | B9: Üsküdar (Kirazlıtepe) | C9: B3 BOĞAZ HATTI | D9: 0 | E9: 0 | F9: 0 | G9: 0 | H9: 0 | I9: 0 | J9: 0 | K9: 0 | L9: =D9+F9+H9+J9 -> 0 | M9: =E9+G9+I9+K9 -> 0 | N9: =IFERROR(M9/L9,0) -> 0
A10: 6 | B10: Ümraniye | C10: B3 BOĞAZ HATTI | D10: 0 | E10: 0 | F10: 0 | G10: 0 | H10: 0 | I10: 0 | J10: 0 | K10: 0 | L10: =D10+F10+H10+J10 -> 0 | M10: =E10+G10+I10+K10 -> 0 | N10: =IFERROR(M10/L10,0) -> 0
A11: 7 | B11: Kadıköy | C11: B4 MARMARA HATTI | D11: 0 | E11: 0 | F11: 0 | G11: 0 | H11: 0 | I11: 0 | J11: 0 | K11: 0 | L11: =D11+F11+H11+J11 -> 0 | M11: =E11+G11+I11+K11 -> 0 | N11: =IFERROR(M11/L11,0) -> 0
A12: 8 | B12: Kartal | C12: B4 MARMARA HATTI | D12: 0 | E12: 0 | F12: 0 | G12: 0 | H12: 0 | I12: 0 | J12: 0 | K12: 0 | L12: =D12+F12+H12+J12 -> 0 | M12: =E12+G12+I12+K12 -> 0 | N12: =IFERROR(M12/L12,0) -> 0
A13: 9 | B13: Pendik | C13: B4 MARMARA HATTI | D13: 0 | E13: 0 | F13: 0 | G13: 0 | H13: 0 | I13: 0 | J13: 0 | K13: 0 | L13: =D13+F13+H13+J13 -> 0 | M13: =E13+G13+I13+K13 -> 0 | N13: =IFERROR(M13/L13,0) -> 0
L14: =D14+F14+H14+J14 -> 0 | M14: =E14+G14+I14+K14 -> 0 | N14: =IFERROR(M14/L14,0) -> 0
L15: =D15+F15+H15+J15 -> 0 | M15: =E15+G15+I15+K15 -> 0 | N15: =IFERROR(M15/L15,0) -> 0
L16: =D16+F16+H16+J16 -> 0 | M16: =E16+G16+I16+K16 -> 0 | N16: =IFERROR(M16/L16,0) -> 0
L17: =D17+F17+H17+J17 -> 0 | M17: =E17+G17+I17+K17 -> 0 | N17: =IFERROR(M17/L17,0) -> 0
L18: =D18+F18+H18+J18 -> 0 | M18: =E18+G18+I18+K18 -> 0 | N18: =IFERROR(M18/L18,0) -> 0
L19: =D19+F19+H19+J19 -> 0 | M19: =E19+G19+I19+K19 -> 0 | N19: =IFERROR(M19/L19,0) -> 0
B20: İL YÖNETİMİ + KOMİSYON | D20: 0 | E20: 0 | F20: 0 | G20: 0 | H20: 0 | I20: 0 | J20: 0 | K20: 0 | L20: =D20+F20+H20+J20 -> 0 | M20: =E20+G20+I20+K20 -> 0 | N20: =IFERROR(M20/L20,0) -> 0
B21: TOPLAM | D21: =SUM(D5:D20) -> 0 | E21: =SUM(E5:E20) -> 0 | F21: =SUM(F5:F20) -> 0 | G21: =SUM(G5:G20) -> 0 | H21: =SUM(H5:H20) -> 0 | I21: =SUM(I5:I20) -> 0 | J21: =SUM(J5:J20) -> 0 | K21: =SUM(K5:K20) -> 0 | ... M21: =SUM(M5:M20) -> 0 | N21: =IFERROR(M21/L21,0) -> 0
A23: 300 KİŞİ MESELESİ: 9 temsilcilik için ilçe başına ~33 kişi demek — üstelik 5'i kadro erimesi yaşıyor. Yapman gereken: her temsilciyi ara, «kaç kişi getirebilirsin?» diye SOR, rakamı o söylesin. Toplam 300'ün altındaysa Reis'e gerçek rakamı gerekçesiyle sun. Tutmayacağını bildiğin bir sayıya 'tamam' demek, teşkilatta güven kaybının en hızlı yoludur.

Sheet 16 STK Iliskileri
A1: STK VE KURUMSAL İLİŞKİLER — YENİ İLÇELERİN KAPISI
