Workbook

Sheet 0 KULLANIM
A1: YEDİHİLAL İSTANBUL — İLÇE KARNE VE PERFORMANS SİSTEMİ
B3: ◐ LOGO BURAYA | C3: YEDİHİLAL — Yedi Tepeden Yedi Kıtaya
C4: İLKELERİMİZ: İman · İlim · İstişare · İrfan · Hikmet · Ahlak · Hareket
C5: «Nizamsız hâk, nizamlı bâtıla mağlûb olur.» — Mustafa Sabri Efendi
C6: «Biz zaferden değil seferden sorumluyuz.»
C7: Bu dosya, İstanbul'un 39 ilçesinin tamamını kapsar. Temsilciliğimiz olan 9 ilçe AKTİF; kalan 30 ilçe hazır bekliyor — açıldıkça «AKTİF?» sütununu «Evet» yap, sistem onu kendiliğinden sıralamaya ve dashboard'a alır.
B8: ↑ Kurumsal YediHilal logosunu bu kutuya yapıştır (Ekle → Resim).
B10: AYLIK DÖNGÜ — 4 ADIM
B11: Adım | C11: Ne yapılır | D11: KİM YAPAR | E11: Ne zaman
B12: 1 — ARA VE SOR | C12: «2 ARAMA KILAVUZU» sekmesini önüne al. 12 soruyu sırayla sor. Cevapları doğrudan «3 VERİ GİRİŞİ»ne yaz. | D12: Veri ve Raporlama Birimi / arayan görevli | E12: Ayın son haftası
B13: 2 — GİR | C13: Sadece MAVİ (ham veri) sütunları doldur. PUAN sütunlarına DOKUNMA — kendiliğinden hesaplanır. | D13: Arayan görevli | E13: Arama sırasında
B14: 3 — ARŞİVLE | C14: «3 VERİ GİRİŞİ»ndeki TOPLAM sütununu kopyala → «4 AYLIK ARŞİV»de o ayın sütununa DEĞER olarak yapıştır (Ctrl+Shift+V). | D14: Sekreterya (Mücahit Tiryaki) | E14: Ay bitince
B15: 4 — SUN | C15: «5 DASHBOARD» otomatik dolar: sıralama, trend okları, zayıf kriter haritası, grafikler. Ekranı yansıt. | D15: Teşkilatlanma Birim Başkanı | E15: Ayın ilk haftası, Reis'e
A17: YENİ TEMSİLCİLİK AÇILDIĞINDA: «3 VERİ GİRİŞİ»nde o ilçenin satırını bul, «AKTİF?» sütununu «Evet» yap. Hepsi bu. Sıralama, ortalama, dashboard ve grafikler kendiliğinden o ilçeyi de hesaba katar. 39 ilçenin tamamı hazır bekliyor.
B19: BAŞLIKLARI DEĞİŞTİRMEK İSTERSEN
A20: «1 AYAR» sekmesine git. 12 kriterin ADI, TİPİ, KATSAYISI ve MAX PUANI orada — hepsi mavi, hepsi değiştirilebilir. · Kriter adını değiştir → veri girişi, arama kılavuzu ve dashboard başlıkları kendiliğinden değişir. · Katsayı veya max puanı değiştir → 39 ilçenin puanı anında yeniden hesaplanır. · TEK KURAL: max puanların toplamı 100 olmalı. Ayar sayfasında otomatik kontrol var. · Tipler: «Sayı» (adet × katsayı) · «Evet/Hayır» (Var/Yapıldı = tam puan) · «Metin» (anlamlı açıklama = tam puan).
B22: MART 2024 DOĞRULAMASI
A23: Motor, Mart 2024 karnenizin ham verisiyle test edildi. 9 ilçenin 8'i BİREBİR aynı çıkıyor (Bahçelievler 63,00 · Kartal 46,50 · Kadıköy 41,50 · Kağıthane 39,00 · Bağcılar 36,00 · Ümraniye 35,00 · Üsküdar 32,50 · Pendik 30,00). TEK FARK — ESENLER: Orijinalde 59,00, sistemde 58,00. Sebebi: kurumsal ziyaret sayısı 6 ve tabloya 6 puan yazılmış — ama o kriterin tavanı 5. Orijinal tabloda tavan uygulanmamış. Sistem uyguluyor: tavan olmazsa ağırlıklandırma bozulur ve toplam 100'ü aşabilir.

Sheet 1 AYAR
A1: AYAR — KRİTER VE PUANLAMA MOTORU
A3: # | B3: KRİTER ADI (değiştirilebilir) | C3: TİP | D3: KATSAYI | E3: MAX PUAN | F3: PUANLAMA KURALI | G3: Veri Girişi sütunu
A4: 1 | B4: İlçe Yönetim Kurulu kişi sayısı | C4: Sayı | D4: 1 | E4: 20 | F4: Her kişi 1 puan. Tavan 20. | G4: E
A5: 2 | B5: Aylık yapılan YK toplantı sayısı | C5: Sayı | D5: 2.5 | E5: 10 | F5: Her toplantı 2,5 puan. Tavan 10 (4 toplantı = tam puan). | G5: G
A6: 3 | B6: İlçenin kendine ait temsilcilik merkezi var mı? | C6: Evet/Hayır | D6: 0 | E6: 5 | F6: Var = 5, Yok = 0. | G6: I
A7: 4 | B7: Yed-i Hilal Meclisi kişi sayısı | C7: Sayı | D7: 0.5 | E7: 10 | F7: Her kişi 0,5 puan. Tavan 10 (20 kişi). | G7: K
A8: 5 | B8: Yeni gönüllü çalışması katılım sayısı | C8: Sayı | D8: 1 | E8: 10 | F8: Her yeni gönüllü 1 puan. Tavan 10. | G8: M
A9: 6 | B9: «Yatsıya Kadar» programı yapıldı mı? | C9: Evet/Hayır | D9: 0 | E9: 10 | F9: Yapıldı = 10, Yapılmadı = 0. | G9: O
A10: 7 | B10: Sabah Namazı Buluşması yapıldı mı? | C10: Evet/Hayır | D10: 0 | E10: 10 | F10: Yapıldı = 10, Yapılmadı = 0. | G10: Q
A11: 8 | B11: Ortaokul ziyareti (kaç okula?) | C11: Sayı | D11: 1 | E11: 5 | F11: Her okul 1 puan. Tavan 5. | G11: S
A12: 9 | B12: Lise ziyareti (kaç okula?) | C12: Sayı | D12: 1 | E12: 5 | F12: Her okul 1 puan. Tavan 5. | G12: U
A13: 10 | B13: Bağışçı ziyareti (kaç ziyaret?) | C13: Sayı | D13: 1 | E13: 5 | F13: Her ziyaret 1 puan. Tavan 5. | G13: W
A14: 11 | B14: Kurumsal ziyaret (kaç kurum?) | C14: Sayı | D14: 1 | E14: 5 | F14: Her kurum 1 puan. Tavan 5. | G14: Y
A15: 12 | B15: İlçeye özgün çalışma (nerede, ne zaman, ne yapıldı?) | C15: Metin | D15: 0 | E15: 5 | F15: Anlamlı açıklama = 5 puan; boş = 0. | G15: AA
B16: MAX PUAN TOPLAMI | E16: =SUM(E4:E15) -> 100 | F16: =IF(E16=100,"✔ Doğru — toplam 100","✘ HATA: toplam 100 olmalı, şu an "&E16) -> ✔ Doğru — toplam 100
B18: TİP AÇIKLAMASI
B19: Tip | C19: Nasıl puanlanır | D19: Örnek
B20: Sayı | C20: Puan = adet × katsayı; MAX PUAN'ı aşamaz | D20: 12 kişilik YK × 1 = 12 puan · 4 toplantı × 2,5 = 10 puan
B21: Evet/Hayır | C21: «Var» / «Yapıldı» / «Evet» → TAM PUAN; başka her şey 0 | D21: Merkez «Var» → 5 · Sabah namazı «Yapılmadı» → 0
B22: Metin | C22: 3 harften uzun anlamlı açıklama → TAM PUAN; boş → 0 | D22: «Baba-Oğul Etkinlikleri» → 5 puan
B25: SINIF EŞİKLERİ (değiştirilebilir)
B26: Sınıf | C26: Alt sınır | D26: Anlamı | E26: Zorunlu aksiyon
B27: A | C27: 65 | D27: Örnek ilçe | E27: Model olarak sunulur, diğerlerine anlattırılır, yıl sonu ödül
B28: B | C28: 50 | D28: Sağlıklı | E28: Standart takip; bir zayıf kriterde hedef verilir
B29: C | C29: 35 | D29: Riskli | E29: Ay içinde ziyaret + yazılı gelişim planı
B30: D | C30: 0 | D30: Kritik | E30: Temsilci ile birebir görüşme + 60 gün içinde kadro değerlendirmesi
A32: EŞİK NOTU: Mart 2024 İstanbul ortalaması 42,17 ve en yüksek puan 63'tü. Klasik 85/70/50 eşiği kullanılsaydı 9 ilçenin 9'u da C-D çıkardı; bu da karneyi anlamsızlaştırır ve ekibi kırar. Eşikler gerçekliğe göre 65/50/35 kondu. Ortalama yükseldikçe eşiği de yukarı çek — karne gerçeği ölçmeli, moral bozmamalı.

Sheet 2 ARAMA KILAVUZU
A1: ARAMA KILAVUZU — TELEFONDA NE SORULACAK, KİME KAÇ PUAN VERİLECEK
A2: Bu sayfa, arama yapacak görevlinin önüne konur. Görevli PUAN VERMEZ — sadece cevabı yazar. Puanı sistem hesaplar. Görevlinin tek işi: doğru soruyu sormak ve doğru hücreye yazmak.
A3: # | B3: Kriter | C3: TELEFONDA SORULACAK CÜMLE (birebir oku) | D3: Hangi sütuna | E3: Nasıl yazılır | F3: Bu kaç puan eder | G3: DİKKAT / TUZAK | H3: Max
A4: 1 | B4: ='1 AYAR'!B4 -> İlçe Yönetim Kurulu kişi sayısı | C4: «Yönetim kurulunuz kaç kişi? Listede adı olup toplantıya gelmeyeni sayma.» | D4: E | E4: Sadece RAKAM yaz (0, 1, 2, 3...) | F4: Her 1 adet = 1 puan (tavan 20) | G4: En sık şişirilen kalem. 'Listede 18 var' derse sor: 'Son toplantıya kaçı geldi?' | H4: 20
A5: 2 | B5: ='1 AYAR'!B5 -> Aylık yapılan YK toplantı sayısı | C5: «Bu ay kaç kez yönetim kurulu toplantısı yaptınız? Tutanağı var mı?» | D5: G | E5: Sadece RAKAM yaz (0, 1, 2, 3...) | F5: Her 1 adet = 2,5 puan (tavan 10) | G5: Tutanağı olmayan toplantı sayılmaz. 'Yaptık ama yazmadık' = yapılmamıştır. | H5: 10
A6: 3 | B6: ='1 AYAR'!B6 -> İlçenin kendine ait temsilcilik merkezi var mı? | C6: «Kendinize ait, 7/24 kullanabildiğiniz bir merkeziniz var mı?» | D6: I | E6: «Var»/«Yok» veya «Yapıldı»/«Yapılmadı» (açılır menü var) | F6: Var/Yapıldı = 5 puan · Yok/Yapılmadı = 0 | G6: Cami odası paylaşmak 'var' sayılmaz. Kira ödeniyor mu, anahtar sizde mi? | H6: 5
A7: 4 | B7: ='1 AYAR'!B7 -> Yed-i Hilal Meclisi kişi sayısı | C7: «Yed-i Hilal Meclisiniz kaç kişi? Son ne zaman toplandı?» | D7: K | E7: Sadece RAKAM yaz (0, 1, 2, 3...) | F7: Her 1 adet = 0,5 puan (tavan 10) | G7: İsim listesi değil, gerçekten toplanan meclis sorulmalı. | H7: 10
A8: 5 | B8: ='1 AYAR'!B8 -> Yeni gönüllü çalışması katılım sayısı | C8: «Bu ay ilk defa çalışmalarımıza katılan kaç YENİ isim oldu? İsimleri neler?» | D8: M | E8: Sadece RAKAM yaz (0, 1, 2, 3...) | F8: Her 1 adet = 1 puan (tavan 10) | G8: 'Yeni' = bu ay ilk kez gelen. İsimleri de iste — Aday Havuzu'na yazacaksın. | H8: 10
A9: 6 | B9: ='1 AYAR'!B9 -> «Yatsıya Kadar» programı yapıldı mı? | C9: «Bu ay Yatsıya Kadar programı yaptınız mı? Kaç kişi katıldı?» | D9: O | E9: «Var»/«Yok» veya «Yapıldı»/«Yapılmadı» (açılır menü var) | F9: Var/Yapıldı = 10 puan · Yok/Yapılmadı = 0 | G9: Mart 2024'te 9 ilçenin 9'u da yapmamış. Tek soruda 10 puan — en kolay kazanılacak puan burada. | H9: 10
A10: 7 | B10: ='1 AYAR'!B10 -> Sabah Namazı Buluşması yapıldı mı? | C10: «Bu ay sabah namazı buluşması yaptınız mı? Hangi camide, kaç kişi?» | D10: Q | E10: «Var»/«Yok» veya «Yapıldı»/«Yapılmadı» (açılır menü var) | F10: Var/Yapıldı = 10 puan · Yok/Yapılmadı = 0 | G10: Cami adı ve katılım sayısı sorulmadan 'yapıldı' yazılmaz. | H10: 10
A11: 8 | B11: ='1 AYAR'!B11 -> Ortaokul ziyareti (kaç okula?) | C11: «Bu ay kaç ORTAOKULA ziyaret yaptınız? Okul isimleri?» | D11: S | E11: Sadece RAKAM yaz (0, 1, 2, 3...) | F11: Her 1 adet = 1 puan (tavan 5) | G11: Aynı okula 3 kez gitmek 1 okuldur. Okul SAYISI soruluyor. | H11: 5
A12: 9 | B12: ='1 AYAR'!B12 -> Lise ziyareti (kaç okula?) | C12: «Bu ay kaç LİSEYE ziyaret yaptınız? Okul isimleri?» | D12: U | E12: Sadece RAKAM yaz (0, 1, 2, 3...) | F12: Her 1 adet = 1 puan (tavan 5) | G12: İmam-Hatip Liseleri öncelikli. Hangi liseye gidildiğini not al. | H12: 5
A13: 10 | B13: ='1 AYAR'!B13 -> Bağışçı ziyareti (kaç ziyaret?) | C13: «Bu ay kaç bağışçı/hayırsever ziyareti yaptınız?» | D13: W | E13: Sadece RAKAM yaz (0, 1, 2, 3...) | F13: Her 1 adet = 1 puan (tavan 5) | G13: Telefonla arama ziyaret değildir. Yüz yüze görüşme sayılır. | H13: 5
A14: 11 | B14: ='1 AYAR'!B14 -> Kurumsal ziyaret (kaç kurum?) | C14: «Hangi kurumları ziyaret ettiniz? (müftülük, okul idaresi, STK, belediye, esnaf odası)» | D14: Y | E14: Sadece RAKAM yaz (0, 1, 2, 3...) | F14: Her 1 adet = 1 puan (tavan 5) | G14: TAVAN 5'TİR. Mart 2024'te bir ilçeye 6 puan yazılmış — sistem artık buna izin vermiyor. | H14: 5
A15: 12 | B15: ='1 AYAR'!B15 -> İlçeye özgün çalışma (nerede, ne zaman, ne yapıldı?) | C15: «Sadece size özgü, başka ilçede olmayan bir çalışma yaptınız mı? Nerede, ne zaman, kaç kişiyle?» | D15: AA | E15: Açıklamayı CÜMLE olarak yaz | F15: Anlamlı açıklama = 5 puan · boş = 0 | G15: 'Evet yaptık' yetmez. Nerede + ne zaman + kaç kişi yoksa puan yok. | H15: 5
B17: ARAMANIN AKIŞI
A18: # | B18: Aşama | C18: Ne denir / ne yapılır | D18: Süre
A19: 1 | B19: Açılış | C19: «Selamünaleyküm [isim] kardeşim, ben [görevli], İl Teşkilatlanma Komisyonu'ndan arıyorum. Aylık raporunuz için 10 dakikanızı alabilir miyim?» | D19: 1 dk
A20: 2 | B20: Çerçeve | C20: «Bu bir denetim değil; ihtiyacınızı görebilmemiz için. 12 kısa soru soracağım.» | D20: 30 sn
A21: 3 | B21: 12 soru | C21: Yukarıdaki sırayla, birebir sor. Cevabı ANINDA Veri Girişi'ne yaz. Yorum yapma, tartışma. | D21: 6-8 dk
A22: 4 | B22: Yeni isim avı | C22: «Bu ay öne çıkan, görev verilebilecek 2 genç ismi söyler misin?» → Aday Havuzu'na aktar. | D22: 1 dk
A23: 5 | B23: Komşu ilçe sorusu | C23: «Yan ilçede (hedef ilçe adı) tanıdığın var mı? Yeni teşkilat için isim arıyoruz.» → 30 hedef ilçenin kapısı bu soru. | D23: 1 dk
A24: 6 | B24: İhtiyaç sorusu | C24: «Bizden ne bekliyorsun? İl olarak size en çok neyle destek olabiliriz?» | D24: 1 dk
A25: 7 | B25: Kapanış | C25: «Allah razı olsun. Puanın çıkınca sana da göndereceğim.» → Şeffaflık güven verir. | D25: 30 sn
B27: GÖREVLİNİN ALTIN KURALLARI
B28: 1. PUAN VERME. Sen sadece cevabı yazarsın; puanı Excel hesaplar. Böylece kimse 'bana neden az verdin' diyemez.
B29: 2. TAHMİN ETME. 'Şey, galiba 3-4' derse: «Net rakam söyle, yoksa düşüğünü yazacağım.» Belirsizlik daima düşük yazılır.
B30: 3. KANIT SOR. Toplantı için tutanak, program için katılım sayısı, okul için OKUL ADI. Kanıtsız beyan yazılmaz.
B31: 4. AYNI GÜN GİR. Kâğıda not alıp sonra girme — kayıp ve hata buradan çıkar.
B32: 5. TARTIŞMA. İtiraz gelirse: «Ham veriyi ben yazdım, puanı sistem verdi. Yanlış yazdıysam düzeltelim.»
B33: 6. AYIN ORTASINDA HATIRLAT. Ay sonunda tek aramayla 12 soruyu doldurmak zordur. Ayın 15'inde kısa bir hatırlatma araması yap.

Sheet 3 VERI GIRISI
A1: AYLIK VERİ GİRİŞİ — İSTANBUL'UN 39 İLÇESİ (sadece AKTİF olanlar puanlanır)
A2: Değerlendirme ayı: | C2: Mart 2024 | E2: ← Örnek veri: Mart 2024 gerçek karneniz. Yeni ay için ham veri sütunlarını temizle. Yeni temsilcilik açılınca AKTİF? = Evet yap.
A4: Sıra | B4: Bölge | C4: İLÇE | D4: AKTİF? | E4: ='1 AYAR'!B4 -> İlçe Yönetim Kurulu kişi sayısı | G4: ='1 AYAR'!B5 -> Aylık yapılan YK toplantı sayısı | I4: ='1 AYAR'!B6 -> İlçenin kendine ait temsilcilik merkezi var mı? | K4: ='1 AYAR'!B7 -> Yed-i Hilal Meclisi kişi sayısı | M4: ='1 AYAR'!B8 -> Yeni gönüllü çalışması katılım sayısı | O4: ='1 AYAR'!B9 -> «Yatsıya Kadar» programı yapıldı mı? | Q4: ='1 AYAR'!B10 -> Sabah Namazı Buluşması yapıldı mı? | S4: ='1 AYAR'!B11 -> Ortaokul ziyareti (kaç okula?) | U4: ='1 AYAR'!B12 -> Lise ziyareti (kaç okula?) | W4: ='1 AYAR'!B13 -> Bağışçı ziyareti (kaç ziyaret?) | Y4: ='1 AYAR'!B14 -> Kurumsal ziyaret (kaç kurum?) | AA4: ='1 AYAR'!B15 -> İlçeye özgün çalışma (nerede, ne zaman, ne yapıldı?) | AC4: TOPLAM | AD4: SINIF | AE4: Sıralama anahtarı | AF4: Arayan / tarih
E5: Ham veri | F5: PUAN | G5: Ham veri | H5: PUAN | I5: Ham veri | J5: PUAN | K5: Ham veri | L5: PUAN | M5: Ham veri | N5: PUAN | O5: Ham veri | P5: PUAN | Q5: Ham veri | R5: PUAN | S5: Ham veri | T5: PUAN | U5: Ham veri | V5: PUAN | W5: Ham veri | X5: PUAN | Y5: Ham veri | Z5: PUAN | AA5: Ham veri | AB5: PUAN
A6: =IF($D6<>"Evet","",RANK(AC6,$AC$6:$AC$44,0)) | B6: B1 HALİÇ HATTI | C6: Fatih | D6: Hayır | F6: =IF($D6<>"Evet","",IF('1 AYAR'!$C$4="Sayı",MIN(E6*'1 AYAR'!$D$4,'1 AYAR'!$E$4),IF('1 AYAR'!$C$4="Evet/Hayır",IF(OR(E6="Var",E6="Yapıldı",E6="Evet"),'1 AYAR'!$E$4,0),IF(LEN(E6)>3,'1 AYAR'!$E$4,0)))) | H6: =IF($D6<>"Evet","",IF('1 AYAR'!$C$5="Sayı",MIN(G6*'1 AYAR'!$D$5,'1 AYAR'!$E$5),IF('1 AYAR'!$C$5="Evet/Hayır",IF(OR(G6="Var",G6="Yapıldı",G6="Evet"),'1 AYAR'!$E$5,0),IF(LEN(G6)>3,'1 AYAR'!$E$5,0)))) | J6: =IF($D6<>"Evet","",IF('1 AYAR'!$C$6="Sayı",MIN(I6*'1 AYAR'!$D$6,'1 AYAR'!$E$6),IF('1 AYAR'!$C$6="Evet/Hayır",IF(OR(I6="Var",I6="Yapıldı",I6="Evet"),'1 AYAR'!$E$6,0),IF(LEN(I6)>3,'1 AYAR'!$E$6,0)))) | L6: =IF($D6<>"Evet","",IF('1 AYAR'!$C$7="Sayı",MIN(K6*'1 AYAR'!$D$7,'1 AYAR'!$E$7),IF('1 AYAR'!$C$7="Evet/Hayır",IF(OR(K6="Var",K6="Yapıldı",K6="Evet"),'1 AYAR'!$E$7,0),IF(LEN(K6)>3,'1 AYAR'!$E$7,0)))) | N6: =IF($D6<>"Evet","",IF('1 AYAR'!$C$8="Sayı",MIN(M6*'1 AYAR'!$D$8,'1 AYAR'!$E$8),IF('1 AYAR'!$C$8="Evet/Hayır",IF(OR(M6="Var",M6="Yapıldı",M6="Evet"),'1 AYAR'!$E$8,0),IF(LEN(M6)>3,'1 AYAR'!$E$8,0)))) | P6: =IF($D6<>"Evet","",IF('1 AYAR'!$C$9="Sayı",MIN(O6*'1 AYAR'!$D$9,'1 AYAR'!$E$9),IF('1 AYAR'!$C$9="Evet/Hayır",IF(OR(O6="Var",O6="Yapıldı",O6="Evet"),'1 AYAR'!$E$9,0),IF(LEN(O6)>3,'1 AYAR'!$E$9,0)))) | R6: =IF($D6<>"Evet","",IF('1 AYAR'!$C$10="Sayı",MIN(Q6*'1 AYAR'!$D$10,'1 AYAR'!$E$10),IF('1 AYAR'!$C$10="Evet/Hayır",IF(OR(Q6="Var",Q6="Yapıldı",Q6="Evet"),'1 AYAR'!$E$10,0),IF(LEN(Q6)>3,'1 AYAR'!$E$10,0)))) | T6: =IF($D6<>"Evet","",IF('1 AYAR'!$C$11="Sayı",MIN(S6*'1 AYAR'!$D$11,'1 AYAR'!$E$11),IF('1 AYAR'!$C$11="Evet/Hayır",IF(OR(S6="Var",S6="Yapıldı",S6="Evet"),'1 AYAR'!$E$11,0),IF(LEN(S6)>3,'1 AYAR'!$E$11,0)))) | V6: =IF($D6<>"Evet","",IF('1 AYAR'!$C$12="Sayı",MIN(U6*'1 AYAR'!$D$12,'1 AYAR'!$E$12),IF('1 AYAR'!$C$12="Evet/Hayır",IF(OR(U6="Var",U6="Yapıldı",U6="Evet"),'1 AYAR'!$E$12,0),IF(LEN(U6)>3,'1 AYAR'!$E$12,0)))) | X6: =IF($D6<>"Evet","",IF('1 AYAR'!$C$13="Sayı",MIN(W6*'1 AYAR'!$D$13,'1 AYAR'!$E$13),IF('1 AYAR'!$C$13="Evet/Hayır",IF(OR(W6="Var",W6="Yapıldı",W6="Evet"),'1 AYAR'!$E$13,0),IF(LEN(W6)>3,'1 AYAR'!$E$13,0)))) | Z6: =IF($D6<>"Evet","",IF('1 AYAR'!$C$14="Sayı",MIN(Y6*'1 AYAR'!$D$14,'1 AYAR'!$E$14),IF('1 AYAR'!$C$14="Evet/Hayır",IF(OR(Y6="Var",Y6="Yapıldı",Y6="Evet"),'1 AYAR'!$E$14,0),IF(LEN(Y6)>3,'1 AYAR'!$E$14,0)))) | AB6: =IF($D6<>"Evet","",IF('1 AYAR'!$C$15="Sayı",MIN(AA6*'1 AYAR'!$D$15,'1 AYAR'!$E$15),IF('1 AYAR'!$C$15="Evet/Hayır",IF(OR(AA6="Var",AA6="Yapıldı",AA6="Evet"),'1 AYAR'!$E$15,0),IF(LEN(AA6)>3,'1 AYAR'!$E$15,0)))) | AC6: =IF($D6<>"Evet","",F6+H6+J6+L6+N6+P6+R6+T6+V6+X6+Z6+AB6) | AD6: =IF($D6<>"Evet","",IF(AC6>='1 AYAR'!$C$27,"A",IF(AC6>='1 AYAR'!$C$28,"B",IF(AC6>='1 AYAR'!$C$29,"C","D")))) | AE6: =IF($D6<>"Evet","",AC6+ROW()/10000)
A7: =IF($D7<>"Evet","",RANK(AC7,$AC$6:$AC$44,0)) | B7: B1 HALİÇ HATTI | C7: Eyüpsultan | D7: Hayır | F7: =IF($D7<>"Evet","",IF('1 AYAR'!$C$4="Sayı",MIN(E7*'1 AYAR'!$D$4,'1 AYAR'!$E$4),IF('1 AYAR'!$C$4="Evet/Hayır",IF(OR(E7="Var",E7="Yapıldı",E7="Evet"),'1 AYAR'!$E$4,0),IF(LEN(E7)>3,'1 AYAR'!$E$4,0)))) | H7: =IF($D7<>"Evet","",IF('1 AYAR'!$C$5="Sayı",MIN(G7*'1 AYAR'!$D$5,'1 AYAR'!$E$5),IF('1 AYAR'!$C$5="Evet/Hayır",IF(OR(G7="Var",G7="Yapıldı",G7="Evet"),'1 AYAR'!$E$5,0),IF(LEN(G7)>3,'1 AYAR'!$E$5,0)))) | J7: =IF($D7<>"Evet","",IF('1 AYAR'!$C$6="Sayı",MIN(I7*'1 AYAR'!$D$6,'1 AYAR'!$E$6),IF('1 AYAR'!$C$6="Evet/Hayır",IF(OR(I7="Var",I7="Yapıldı",I7="Evet"),'1 AYAR'!$E$6,0),IF(LEN(I7)>3,'1 AYAR'!$E$6,0)))) | L7: =IF($D7<>"Evet","",IF('1 AYAR'!$C$7="Sayı",MIN(K7*'1 AYAR'!$D$7,'1 AYAR'!$E$7),IF('1 AYAR'!$C$7="Evet/Hayır",IF(OR(K7="Var",K7="Yapıldı",K7="Evet"),'1 AYAR'!$E$7,0),IF(LEN(K7)>3,'1 AYAR'!$E$7,0)))) | N7: =IF($D7<>"Evet","",IF('1 AYAR'!$C$8="Sayı",MIN(M7*'1 AYAR'!$D$8,'1 AYAR'!$E$8),IF('1 AYAR'!$C$8="Evet/Hayır",IF(OR(M7="Var",M7="Yapıldı",M7="Evet"),'1 AYAR'!$E$8,0),IF(LEN(M7)>3,'1 AYAR'!$E$8,0)))) | P7: =IF($D7<>"Evet","",IF('1 AYAR'!$C$9="Sayı",MIN(O7*'1 AYAR'!$D$9,'1 AYAR'!$E$9),IF('1 AYAR'!$C$9="Evet/Hayır",IF(OR(O7="Var",O7="Yapıldı",O7="Evet"),'1 AYAR'!$E$9,0),IF(LEN(O7)>3,'1 AYAR'!$E$9,0)))) | R7: =IF($D7<>"Evet","",IF('1 AYAR'!$C$10="Sayı",MIN(Q7*'1 AYAR'!$D$10,'1 AYAR'!$E$10),IF('1 AYAR'!$C$10="Evet/Hayır",IF(OR(Q7="Var",Q7="Yapıldı",Q7="Evet"),'1 AYAR'!$E$10,0),IF(LEN(Q7)>3,'1 AYAR'!$E$10,0)))) | T7: =IF($D7<>"Evet","",IF('1 AYAR'!$C$11="Sayı",MIN(S7*'1 AYAR'!$D$11,'1 AYAR'!$E$11),IF('1 AYAR'!$C$11="Evet/Hayır",IF(OR(S7="Var",S7="Yapıldı",S7="Evet"),'1 AYAR'!$E$11,0),IF(LEN(S7)>3,'1 AYAR'!$E$11,0)))) | V7: =IF($D7<>"Evet","",IF('1 AYAR'!$C$12="Sayı",MIN(U7*'1 AYAR'!$D$12,'1 AYAR'!$E$12),IF('1 AYAR'!$C$12="Evet/Hayır",IF(OR(U7="Var",U7="Yapıldı",U7="Evet"),'1 AYAR'!$E$12,0),IF(LEN(U7)>3,'1 AYAR'!$E$12,0)))) | X7: =IF($D7<>"Evet","",IF('1 AYAR'!$C$13="Sayı",MIN(W7*'1 AYAR'!$D$13,'1 AYAR'!$E$13),IF('1 AYAR'!$C$13="Evet/Hayır",IF(OR(W7="Var",W7="Yapıldı",W7="Evet"),'1 AYAR'!$E$13,0),IF(LEN(W7)>3,'1 AYAR'!$E$13,0)))) | Z7: =IF($D7<>"Evet","",IF('1 AYAR'!$C$14="Sayı",MIN(Y7*'1 AYAR'!$D$14,'1 AYAR'!$E$14),IF('1 AYAR'!$C$14="Evet/Hayır",IF(OR(Y7="Var",Y7="Yapıldı",Y7="Evet"),'1 AYAR'!$E$14,0),IF(LEN(Y7)>3,'1 AYAR'!$E$14,0)))) | AB7: =IF($D7<>"Evet","",IF('1 AYAR'!$C$15="Sayı",MIN(AA7*'1 AYAR'!$D$15,'1 AYAR'!$E$15),IF('1 AYAR'!$C$15="Evet/Hayır",IF(OR(AA7="Var",AA7="Yapıldı",AA7="Evet"),'1 AYAR'!$E$15,0),IF(LEN(AA7)>3,'1 AYAR'!$E$15,0)))) | AC7: =IF($D7<>"Evet","",F7+H7+J7+L7+N7+P7+R7+T7+V7+X7+Z7+AB7) | AD7: =IF($D7<>"Evet","",IF(AC7>='1 AYAR'!$C$27,"A",IF(AC7>='1 AYAR'!$C$28,"B",IF(AC7>='1 AYAR'!$C$29,"C","D")))) | AE7: =IF($D7<>"Evet","",AC7+ROW()/10000)
A8: =IF($D8<>"Evet","",RANK(AC8,$AC$6:$AC$44,0)) | B8: B1 HALİÇ HATTI | C8: Gaziosmanpaşa | D8: Hayır | F8: =IF($D8<>"Evet","",IF('1 AYAR'!$C$4="Sayı",MIN(E8*'1 AYAR'!$D$4,'1 AYAR'!$E$4),IF('1 AYAR'!$C$4="Evet/Hayır",IF(OR(E8="Var",E8="Yapıldı",E8="Evet"),'1 AYAR'!$E$4,0),IF(LEN(E8)>3,'1 AYAR'!$E$4,0)))) | H8: =IF($D8<>"Evet","",IF('1 AYAR'!$C$5="Sayı",MIN(G8*'1 AYAR'!$D$5,'1 AYAR'!$E$5),IF('1 AYAR'!$C$5="Evet/Hayır",IF(OR(G8="Var",G8="Yapıldı",G8="Evet"),'1 AYAR'!$E$5,0),IF(LEN(G8)>3,'1 AYAR'!$E$5,0)))) | J8: =IF($D8<>"Evet","",IF('1 AYAR'!$C$6="Sayı",MIN(I8*'1 AYAR'!$D$6,'1 AYAR'!$E$6),IF('1 AYAR'!$C$6="Evet/Hayır",IF(OR(I8="Var",I8="Yapıldı",I8="Evet"),'1 AYAR'!$E$6,0),IF(LEN(I8)>3,'1 AYAR'!$E$6,0)))) | L8: =IF($D8<>"Evet","",IF('1 AYAR'!$C$7="Sayı",MIN(K8*'1 AYAR'!$D$7,'1 AYAR'!$E$7),IF('1 AYAR'!$C$7="Evet/Hayır",IF(OR(K8="Var",K8="Yapıldı",K8="Evet"),'1 AYAR'!$E$7,0),IF(LEN(K8)>3,'1 AYAR'!$E$7,0)))) | N8: =IF($D8<>"Evet","",IF('1 AYAR'!$C$8="Sayı",MIN(M8*'1 AYAR'!$D$8,'1 AYAR'!$E$8),IF('1 AYAR'!$C$8="Evet/Hayır",IF(OR(M8="Var",M8="Yapıldı",M8="Evet"),'1 AYAR'!$E$8,0),IF(LEN(M8)>3,'1 AYAR'!$E$8,0)))) | P8: =IF($D8<>"Evet","",IF('1 AYAR'!$C$9="Sayı",MIN(O8*'1 AYAR'!$D$9,'1 AYAR'!$E$9),IF('1 AYAR'!$C$9="Evet/Hayır",IF(OR(O8="Var",O8="Yapıldı",O8="Evet"),'1 AYAR'!$E$9,0),IF(LEN(O8)>3,'1 AYAR'!$E$9,0)))) | R8: =IF($D8<>"Evet","",IF('1 AYAR'!$C$10="Sayı",MIN(Q8*'1 AYAR'!$D$10,'1 AYAR'!$E$10),IF('1 AYAR'!$C$10="Evet/Hayır",IF(OR(Q8="Var",Q8="Yapıldı",Q8="Evet"),'1 AYAR'!$E$10,0),IF(LEN(Q8)>3,'1 AYAR'!$E$10,0)))) | T8: =IF($D8<>"Evet","",IF('1 AYAR'!$C$11="Sayı",MIN(S8*'1 AYAR'!$D$11,'1 AYAR'!$E$11),IF('1 AYAR'!$C$11="Evet/Hayır",IF(OR(S8="Var",S8="Yapıldı",S8="Evet"),'1 AYAR'!$E$11,0),IF(LEN(S8)>3,'1 AYAR'!$E$11,0)))) | V8: =IF($D8<>"Evet","",IF('1 AYAR'!$C$12="Sayı",MIN(U8*'1 AYAR'!$D$12,'1 AYAR'!$E$12),IF('1 AYAR'!$C$12="Evet/Hayır",IF(OR(U8="Var",U8="Yapıldı",U8="Evet"),'1 AYAR'!$E$12,0),IF(LEN(U8)>3,'1 AYAR'!$E$12,0)))) | X8: =IF($D8<>"Evet","",IF('1 AYAR'!$C$13="Sayı",MIN(W8*'1 AYAR'!$D$13,'1 AYAR'!$E$13),IF('1 AYAR'!$C$13="Evet/Hayır",IF(OR(W8="Var",W8="Yapıldı",W8="Evet"),'1 AYAR'!$E$13,0),IF(LEN(W8)>3,'1 AYAR'!$E$13,0)))) | Z8: =IF($D8<>"Evet","",IF('1 AYAR'!$C$14="Sayı",MIN(Y8*'1 AYAR'!$D$14,'1 AYAR'!$E$14),IF('1 AYAR'!$C$14="Evet/Hayır",IF(OR(Y8="Var",Y8="Yapıldı",Y8="Evet"),'1 AYAR'!$E$14,0),IF(LEN(Y8)>3,'1 AYAR'!$E$14,0)))) | AB8: =IF($D8<>"Evet","",IF('1 AYAR'!$C$15="Sayı",MIN(AA8*'1 AYAR'!$D$15,'1 AYAR'!$E$15),IF('1 AYAR'!$C$15="Evet/Hayır",IF(OR(AA8="Var",AA8="Yapıldı",AA8="Evet"),'1 AYAR'!$E$15,0),IF(LEN(AA8)>3,'1 AYAR'!$E$15,0)))) | AC8: =IF($D8<>"Evet","",F8+H8+J8+L8+N8+P8+R8+T8+V8+X8+Z8+AB8) | AD8: =IF($D8<>"Evet","",IF(AC8>='1 AYAR'!$C$27,"A",IF(AC8>='1 AYAR'!$C$28,"B",IF(AC8>='1 AYAR'!$C$29,"C","D")))) | AE8: =IF($D8<>"Evet","",AC8+ROW()/10000)
A9: =IF($D9<>"Evet","",RANK(AC9,$AC$6:$AC$44,0)) | B9: B1 HALİÇ HATTI | C9: Sultangazi | D9: Hayır | F9: =IF($D9<>"Evet","",IF('1 AYAR'!$C$4="Sayı",MIN(E9*'1 AYAR'!$D$4,'1 AYAR'!$E$4),IF('1 AYAR'!$C$4="Evet/Hayır",IF(OR(E9="Var",E9="Yapıldı",E9="Evet"),'1 AYAR'!$E$4,0),IF(LEN(E9)>3,'1 AYAR'!$E$4,0)))) | H9: =IF($D9<>"Evet","",IF('1 AYAR'!$C$5="Sayı",MIN(G9*'1 AYAR'!$D$5,'1 AYAR'!$E$5),IF('1 AYAR'!$C$5="Evet/Hayır",IF(OR(G9="Var",G9="Yapıldı",G9="Evet"),'1 AYAR'!$E$5,0),IF(LEN(G9)>3,'1 AYAR'!$E$5,0)))) | J9: =IF($D9<>"Evet","",IF('1 AYAR'!$C$6="Sayı",MIN(I9*'1 AYAR'!$D$6,'1 AYAR'!$E$6),IF('1 AYAR'!$C$6="Evet/Hayır",IF(OR(I9="Var",I9="Yapıldı",I9="Evet"),'1 AYAR'!$E$6,0),IF(LEN(I9)>3,'1 AYAR'!$E$6,0)))) | L9: =IF($D9<>"Evet","",IF('1 AYAR'!$C$7="Sayı",MIN(K9*'1 AYAR'!$D$7,'1 AYAR'!$E$7),IF('1 AYAR'!$C$7="Evet/Hayır",IF(OR(K9="Var",K9="Yapıldı",K9="Evet"),'1 AYAR'!$E$7,0),IF(LEN(K9)>3,'1 AYAR'!$E$7,0)))) | N9: =IF($D9<>"Evet","",IF('1 AYAR'!$C$8="Sayı",MIN(M9*'1 AYAR'!$D$8,'1 AYAR'!$E$8),IF('1 AYAR'!$C$8="Evet/Hayır",IF(OR(M9="Var",M9="Yapıldı",M9="Evet"),'1 AYAR'!$E$8,0),IF(LEN(M9)>3,'1 AYAR'!$E$8,0)))) | P9: =IF($D9<>"Evet","",IF('1 AYAR'!$C$9="Sayı",MIN(O9*'1 AYAR'!$D$9,'1 AYAR'!$E$9),IF('1 AYAR'!$C$9="Evet/Hayır",IF(OR(O9="Var",O9="Yapıldı",O9="Evet"),'1 AYAR'!$E$9,0),IF(LEN(O9)>3,'1 AYAR'!$E$9,0)))) | R9: =IF($D9<>"Evet","",IF('1 AYAR'!$C$10="Sayı",MIN(Q9*'1 AYAR'!$D$10,'1 AYAR'!$E$10),IF('1 AYAR'!$C$10="Evet/Hayır",IF(OR(Q9="Var",Q9="Yapıldı",Q9="Evet"),'1 AYAR'!$E$10,0),IF(LEN(Q9)>3,'1 AYAR'!$E$10,0)))) | T9: =IF($D9<>"Evet","",IF('1 AYAR'!$C$11="Sayı",MIN(S9*'1 AYAR'!$D$11,'1 AYAR'!$E$11),IF('1 AYAR'!$C$11="Evet/Hayır",IF(OR(S9="Var",S9="Yapıldı",S9="Evet"),'1 AYAR'!$E$11,0),IF(LEN(S9)>3,'1 AYAR'!$E$11,0)))) | V9: =IF($D9<>"Evet","",IF('1 AYAR'!$C$12="Sayı",MIN(U9*'1 AYAR'!$D$12,'1 AYAR'!$E$12),IF('1 AYAR'!$C$12="Evet/Hayır",IF(OR(U9="Var",U9="Yapıldı",U9="Evet"),'1 AYAR'!$E$12,0),IF(LEN(U9)>3,'1 AYAR'!$E$12,0)))) | X9: =IF($D9<>"Evet","",IF('1 AYAR'!$C$13="Sayı",MIN(W9*'1 AYAR'!$D$13,'1 AYAR'!$E$13),IF('1 AYAR'!$C$13="Evet/Hayır",IF(OR(W9="Var",W9="Yapıldı",W9="Evet"),'1 AYAR'!$E$13,0),IF(LEN(W9)>3,'1 AYAR'!$E$13,0)))) | Z9: =IF($D9<>"Evet","",IF('1 AYAR'!$C$14="Sayı",MIN(Y9*'1 AYAR'!$D$14,'1 AYAR'!$E$14),IF('1 AYAR'!$C$14="Evet/Hayır",IF(OR(Y9="Var",Y9="Yapıldı",Y9="Evet"),'1 AYAR'!$E$14,0),IF(LEN(Y9)>3,'1 AYAR'!$E$14,0)))) | AB9: =IF($D9<>"Evet","",IF('1 AYAR'!$C$15="Sayı",MIN(AA9*'1 AYAR'!$D$15,'1 AYAR'!$E$15),IF('1 AYAR'!$C$15="Evet/Hayır",IF(OR(AA9="Var",AA9="Yapıldı",AA9="Evet"),'1 AYAR'!$E$15,0),IF(LEN(AA9)>3,'1 AYAR'!$E$15,0)))) | AC9: =IF($D9<>"Evet","",F9+H9+J9+L9+N9+P9+R9+T9+V9+X9+Z9+AB9) | AD9: =IF($D9<>"Evet","",IF(AC9>='1 AYAR'!$C$27,"A",IF(AC9>='1 AYAR'!$C$28,"B",IF(AC9>='1 AYAR'!$C$29,"C","D")))) | AE9: =IF($D9<>"Evet","",AC9+ROW()/10000)
A10: =IF($D10<>"Evet","",RANK(AC10,$AC$6:$AC$44,0)) | B10: B1 HALİÇ HATTI | C10: Bayrampaşa | D10: Hayır | F10: =IF($D10<>"Evet","",IF('1 AYAR'!$C$4="Sayı",MIN(E10*'1 AYAR'!$D$4,'1 AYAR'!$E$4),IF('1 AYAR'!$C$4="Evet/Hayır",IF(OR(E10="Var",E10="Yapıldı",E10="Evet"),'1 AYAR'!$E$4,0),IF(LEN(E10)>3,'1 AYAR'!$E$4,0)))) | H10: =IF($D10<>"Evet","",IF('1 AYAR'!$C$5="Sayı",MIN(G10*'1 AYAR'!$D$5,'1 AYAR'!$E$5),IF('1 AYAR'!$C$5="Evet/Hayır",IF(OR(G10="Var",G10="Yapıldı",G10="Evet"),'1 AYAR'!$E$5,0),IF(LEN(G10)>3,'1 AYAR'!$E$5,0)))) | J10: =IF($D10<>"Evet","",IF('1 AYAR'!$C$6="Sayı",MIN(I10*'1 AYAR'!$D$6,'1 AYAR'!$E$6),IF('1 AYAR'!$C$6="Evet/Hayır",IF(OR(I10="Var",I10="Yapıldı",I10="Evet"),'1 AYAR'!$E$6,0),IF(LEN(I10)>3,'1 AYAR'!$E$6,0)))) | L10: =IF($D10<>"Evet","",IF('1 AYAR'!$C$7="Sayı",MIN(K10*'1 AYAR'!$D$7,'1 AYAR'!$E$7),IF('1 AYAR'!$C$7="Evet/Hayır",IF(OR(K10="Var",K10="Yapıldı",K10="Evet"),'1 AYAR'!$E$7,0),IF(LEN(K10)>3,'1 AYAR'!$E$7,0)))) | N10: =IF($D10<>"Evet","",IF('1 AYAR'!$C$8="Sayı",MIN(M10*'1 AYAR'!$D$8,'1 AYAR'!$E$8),IF('1 AYAR'!$C$8="Evet/Hayır",IF(OR(M10="Var",M10="Yapıldı",M10="Evet"),'1 AYAR'!$E$8,0),IF(LEN(M10)>3,'1 AYAR'!$E$8,0)))) | P10: =IF($D10<>"Evet","",IF('1 AYAR'!$C$9="Sayı",MIN(O10*'1 AYAR'!$D$9,'1 AYAR'!$E$9),IF('1 AYAR'!$C$9="Evet/Hayır",IF(OR(O10="Var",O10="Yapıldı",O10="Evet"),'1 AYAR'!$E$9,0),IF(LEN(O10)>3,'1 AYAR'!$E$9,0)))) | R10: =IF($D10<>"Evet","",IF('1 AYAR'!$C$10="Sayı",MIN(Q10*'1 AYAR'!$D$10,'1 AYAR'!$E$10),IF('1 AYAR'!$C$10="Evet/Hayır",IF(OR(Q10="Var",Q10="Yapıldı",Q10="Evet"),'1 AYAR'!$E$10,0),IF(LEN(Q10)>3,'1 AYAR'!$E$10,0)))) | T10: =IF($D10<>"Evet","",IF('1 AYAR'!$C$11="Sayı",MIN(S10*'1 AYAR'!$D$11,'1 AYAR'!$E$11),IF('1 AYAR'!$C$11="Evet/Hayır",IF(OR(S10="Var",S10="Yapıldı",S10="Evet"),'1 AYAR'!$E$11,0),IF(LEN(S10)>3,'1 AYAR'!$E$11,0)))) | V10: =IF($D10<>"Evet","",IF('1 AYAR'!$C$12="Sayı",MIN(U10*'1 AYAR'!$D$12,'1 AYAR'!$E$12),IF('1 AYAR'!$C$12="Evet/Hayır",IF(OR(U10="Var",U10="Yapıldı",U10="Evet"),'1 AYAR'!$E$12,0),IF(LEN(U10)>3,'1 AYAR'!$E$12,0)))) | X10: =IF($D10<>"Evet","",IF('1 AYAR'!$C$13="Sayı",MIN(W10*'1 AYAR'!$D$13,'1 AYAR'!$E$13),IF('1 AYAR'!$C$13="Evet/Hayır",IF(OR(W10="Var",W10="Yapıldı",W10="Evet"),'1 AYAR'!$E$13,0),IF(LEN(W10)>3,'1 AYAR'!$E$13,0)))) | Z10: =IF($D10<>"Evet","",IF('1 AYAR'!$C$14="Sayı",MIN(Y10*'1 AYAR'!$D$14,'1 AYAR'!$E$14),IF('1 AYAR'!$C$14="Evet/Hayır",IF(OR(Y10="Var",Y10="Yapıldı",Y10="Evet"),'1 AYAR'!$E$14,0),IF(LEN(Y10)>3,'1 AYAR'!$E$14,0)))) | AB10: =IF($D10<>"Evet","",IF('1 AYAR'!$C$15="Sayı",MIN(AA10*'1 AYAR'!$D$15,'1 AYAR'!$E$15),IF('1 AYAR'!$C$15="Evet/Hayır",IF(OR(AA10="Var",AA10="Yapıldı",AA10="Evet"),'1 AYAR'!$E$15,0),IF(LEN(AA10)>3,'1 AYAR'!$E$15,0)))) | AC10: =IF($D10<>"Evet","",F10+H10+J10+L10+N10+P10+R10+T10+V10+X10+Z10+AB10) | AD10: =IF($D10<>"Evet","",IF(AC10>='1 AYAR'!$C$27,"A",IF(AC10>='1 AYAR'!$C$28,"B",IF(AC10>='1 AYAR'!$C$29,"C","D")))) | AE10: =IF($D10<>"Evet","",AC10+ROW()/10000)
A11: =IF($D11<>"Evet","",RANK(AC11,$AC$6:$AC$44,0)) -> 5 | B11: B1 HALİÇ HATTI | C11: Kağıthane | D11: Evet | E11: 10 | F11: =IF($D11<>"Evet","",IF('1 AYAR'!$C$4="Sayı",MIN(E11*'1 AYAR'!$D$4,'1 AYAR'!$E$4),IF('1 AYAR'!$C$4="Evet/Hayır",IF(OR(E11="Var",E11="Yapıldı",E11="Evet"),'1 AYAR'!$E$4,0),IF(LEN(E11)>3,'1 AYAR'!$E$4,0)))) -> 10 | G11: 3 | H11: =IF($D11<>"Evet","",IF('1 AYAR'!$C$5="Sayı",MIN(G11*'1 AYAR'!$D$5,'1 AYAR'!$E$5),IF('1 AYAR'!$C$5="Evet/Hayır",IF(OR(G11="Var",G11="Yapıldı",G11="Evet"),'1 AYAR'!$E$5,0),IF(LEN(G11)>3,'1 AYAR'!$E$5,0)))) -> 7.5 | I11: Yok | J11: =IF($D11<>"Evet","",IF('1 AYAR'!$C$6="Sayı",MIN(I11*'1 AYAR'!$D$6,'1 AYAR'!$E$6),IF('1 AYAR'!$C$6="Evet/Hayır",IF(OR(I11="Var",I11="Yapıldı",I11="Evet"),'1 AYAR'!$E$6,0),IF(LEN(I11)>3,'1 AYAR'!$E$6,0)))) -> 0 | K11: 3 | L11: =IF($D11<>"Evet","",IF('1 AYAR'!$C$7="Sayı",MIN(K11*'1 AYAR'!$D$7,'1 AYAR'!$E$7),IF('1 AYAR'!$C$7="Evet/Hayır",IF(OR(K11="Var",K11="Yapıldı",K11="Evet"),'1 AYAR'!$E$7,0),IF(LEN(K11)>3,'1 AYAR'!$E$7,0)))) -> 1.5 | M11: 3 | N11: =IF($D11<>"Evet","",IF('1 AYAR'!$C$8="Sayı",MIN(M11*'1 AYAR'!$D$8,'1 AYAR'!$E$8),IF('1 AYAR'!$C$8="Evet/Hayır",IF(OR(M11="Var",M11="Yapıldı",M11="Evet"),'1 AYAR'!$E$8,0),IF(LEN(M11)>3,'1 AYAR'!$E$8,0)))) -> 3 | O11: Yapılmadı | P11: =IF($D11<>"Evet","",IF('1 AYAR'!$C$9="Sayı",MIN(O11*'1 AYAR'!$D$9,'1 AYAR'!$E$9),IF('1 AYAR'!$C$9="Evet/Hayır",IF(OR(O11="Var",O11="Yapıldı",O11="Evet"),'1 AYAR'!$E$9,0),IF(LEN(O11)>3,'1 AYAR'!$E$9,0)))) -> 0 | Q11: Yapıldı | R11: =IF($D11<>"Evet","",IF('1 AYAR'!$C$10="Sayı",MIN(Q11*'1 AYAR'!$D$10,'1 AYAR'!$E$10),IF('1 AYAR'!$C$10="Evet/Hayır",IF(OR(Q11="Var",Q11="Yapıldı",Q11="Evet"),'1 AYAR'!$E$10,0),IF(LEN(Q11)>3,'1 AYAR'!$E$10,0)))) -> 10 | S11: 1 | T11: =IF($D11<>"Evet","",IF('1 AYAR'!$C$11="Sayı",MIN(S11*'1 AYAR'!$D$11,'1 AYAR'!$E$11),IF('1 AYAR'!$C$11="Evet/Hayır",IF(OR(S11="Var",S11="Yapıldı",S11="Evet"),'1 AYAR'!$E$11,0),IF(LEN(S11)>3,'1 AYAR'!$E$11,0)))) -> 1 | U11: 1 | V11: =IF($D11<>"Evet","",IF('1 AYAR'!$C$12="Sayı",MIN(U11*'1 AYAR'!$D$12,'1 AYAR'!$E$12),IF('1 AYAR'!$C$12="Evet/Hayır",IF(OR(U11="Var",U11="Yapıldı",U11="Evet"),'1 AYAR'!$E$12,0),IF(LEN(U11)>3,'1 AYAR'!$E$12,0)))) -> 1 | W11: 0 | X11: =IF($D11<>"Evet","",IF('1 AYAR'!$C$13="Sayı",MIN(W11*'1 AYAR'!$D$13,'1 AYAR'!$E$13),IF('1 AYAR'!$C$13="Evet/Hayır",IF(OR(W11="Var",W11="Yapıldı",W11="Evet"),'1 AYAR'!$E$13,0),IF(LEN(W11)>3,'1 AYAR'!$E$13,0)))) -> 0 | Y11: 0 | Z11: =IF($D11<>"Evet","",IF('1 AYAR'!$C$14="Sayı",MIN(Y11*'1 AYAR'!$D$14,'1 AYAR'!$E$14),IF('1 AYAR'!$C$14="Evet/Hayır",IF(OR(Y11="Var",Y11="Yapıldı",Y11="Evet"),'1 AYAR'!$E$14,0),IF(LEN(Y11)>3,'1 AYAR'!$E$14,0)))) -> 0 | AA11: Bir okulda Sahabe Hayatları Dersleri; Ramazan'da okulda iftar | AB11: =IF($D11<>"Evet","",IF('1 AYAR'!$C$15="Sayı",MIN(AA11*'1 AYAR'!$D$15,'1 AYAR'!$E$15),IF('1 AYAR'!$C$15="Evet/Hayır",IF(OR(AA11="Var",AA11="Yapıldı",AA11="Evet"),'1 AYAR'!$E$15,0),IF(LEN(AA11)>3,'1 AYAR'!$E$15,0)))) -> 5 | AC11: =IF($D11<>"Evet","",F11+H11+J11+L11+N11+P11+R11+T11+V11+X11+Z11+AB11) -> 39 | AD11: =IF($D11<>"Evet","",IF(AC11>='1 AYAR'!$C$27,"A",IF(AC11>='1 AYAR'!$C$28,"B",IF(AC11>='1 AYAR'!$C$29,"C","D")))) -> C | AE11: =IF($D11<>"Evet","",AC11+ROW()/10000) -> 39.0011
A12: =IF($D12<>"Evet","",RANK(AC12,$AC$6:$AC$44,0)) | B12: B1 HALİÇ HATTI | C12: Beyoğlu | D12: Hayır | F12: =IF($D12<>"Evet","",IF('1 AYAR'!$C$4="Sayı",MIN(E12*'1 AYAR'!$D$4,'1 AYAR'!$E$4),IF('1 AYAR'!$C$4="Evet/Hayır",IF(OR(E12="Var",E12="Yapıldı",E12="Evet"),'1 AYAR'!$E$4,0),IF(LEN(E12)>3,'1 AYAR'!$E$4,0)))) | H12: =IF($D12<>"Evet","",IF('1 AYAR'!$C$5="Sayı",MIN(G12*'1 AYAR'!$D$5,'1 AYAR'!$E$5),IF('1 AYAR'!$C$5="Evet/Hayır",IF(OR(G12="Var",G12="Yapıldı",G12="Evet"),'1 AYAR'!$E$5,0),IF(LEN(G12)>3,'1 AYAR'!$E$5,0)))) | J12: =IF($D12<>"Evet","",IF('1 AYAR'!$C$6="Sayı",MIN(I12*'1 AYAR'!$D$6,'1 AYAR'!$E$6),IF('1 AYAR'!$C$6="Evet/Hayır",IF(OR(I12="Var",I12="Yapıldı",I12="Evet"),'1 AYAR'!$E$6,0),IF(LEN(I12)>3,'1 AYAR'!$E$6,0)))) | L12: =IF($D12<>"Evet","",IF('1 AYAR'!$C$7="Sayı",MIN(K12*'1 AYAR'!$D$7,'1 AYAR'!$E$7),IF('1 AYAR'!$C$7="Evet/Hayır",IF(OR(K12="Var",K12="Yapıldı",K12="Evet"),'1 AYAR'!$E$7,0),IF(LEN(K12)>3,'1 AYAR'!$E$7,0)))) | N12: =IF($D12<>"Evet","",IF('1 AYAR'!$C$8="Sayı",MIN(M12*'1 AYAR'!$D$8,'1 AYAR'!$E$8),IF('1 AYAR'!$C$8="Evet/Hayır",IF(OR(M12="Var",M12="Yapıldı",M12="Evet"),'1 AYAR'!$E$8,0),IF(LEN(M12)>3,'1 AYAR'!$E$8,0)))) | P12: =IF($D12<>"Evet","",IF('1 AYAR'!$C$9="Sayı",MIN(O12*'1 AYAR'!$D$9,'1 AYAR'!$E$9),IF('1 AYAR'!$C$9="Evet/Hayır",IF(OR(O12="Var",O12="Yapıldı",O12="Evet"),'1 AYAR'!$E$9,0),IF(LEN(O12)>3,'1 AYAR'!$E$9,0)))) | R12: =IF($D12<>"Evet","",IF('1 AYAR'!$C$10="Sayı",MIN(Q12*'1 AYAR'!$D$10,'1 AYAR'!$E$10),IF('1 AYAR'!$C$10="Evet/Hayır",IF(OR(Q12="Var",Q12="Yapıldı",Q12="Evet"),'1 AYAR'!$E$10,0),IF(LEN(Q12)>3,'1 AYAR'!$E$10,0)))) | T12: =IF($D12<>"Evet","",IF('1 AYAR'!$C$11="Sayı",MIN(S12*'1 AYAR'!$D$11,'1 AYAR'!$E$11),IF('1 AYAR'!$C$11="Evet/Hayır",IF(OR(S12="Var",S12="Yapıldı",S12="Evet"),'1 AYAR'!$E$11,0),IF(LEN(S12)>3,'1 AYAR'!$E$11,0)))) | V12: =IF($D12<>"Evet","",IF('1 AYAR'!$C$12="Sayı",MIN(U12*'1 AYAR'!$D$12,'1 AYAR'!$E$12),IF('1 AYAR'!$C$12="Evet/Hayır",IF(OR(U12="Var",U12="Yapıldı",U12="Evet"),'1 AYAR'!$E$12,0),IF(LEN(U12)>3,'1 AYAR'!$E$12,0)))) | X12: =IF($D12<>"Evet","",IF('1 AYAR'!$C$13="Sayı",MIN(W12*'1 AYAR'!$D$13,'1 AYAR'!$E$13),IF('1 AYAR'!$C$13="Evet/Hayır",IF(OR(W12="Var",W12="Yapıldı",W12="Evet"),'1 AYAR'!$E$13,0),IF(LEN(W12)>3,'1 AYAR'!$E$13,0)))) | Z12: =IF($D12<>"Evet","",IF('1 AYAR'!$C$14="Sayı",MIN(Y12*'1 AYAR'!$D$14,'1 AYAR'!$E$14),IF('1 AYAR'!$C$14="Evet/Hayır",IF(OR(Y12="Var",Y12="Yapıldı",Y12="Evet"),'1 AYAR'!$E$14,0),IF(LEN(Y12)>3,'1 AYAR'!$E$14,0)))) | AB12: =IF($D12<>"Evet","",IF('1 AYAR'!$C$15="Sayı",MIN(AA12*'1 AYAR'!$D$15,'1 AYAR'!$E$15),IF('1 AYAR'!$C$15="Evet/Hayır",IF(OR(AA12="Var",AA12="Yapıldı",AA12="Evet"),'1 AYAR'!$E$15,0),IF(LEN(AA12)>3,'1 AYAR'!$E$15,0)))) | AC12: =IF($D12<>"Evet","",F12+H12+J12+L12+N12+P12+R12+T12+V12+X12+Z12+AB12) | AD12: =IF($D12<>"Evet","",IF(AC12>='1 AYAR'!$C$27,"A",IF(AC12>='1 AYAR'!$C$28,"B",IF(AC12>='1 AYAR'!$C$29,"C","D")))) | AE12: =IF($D12<>"Evet","",AC12+ROW()/10000)
A13: =IF($D13<>"Evet","",RANK(AC13,$AC$6:$AC$44,0)) | B13: B1 HALİÇ HATTI | C13: Şişli | D13: Hayır | F13: =IF($D13<>"Evet","",IF('1 AYAR'!$C$4="Sayı",MIN(E13*'1 AYAR'!$D$4,'1 AYAR'!$E$4),IF('1 AYAR'!$C$4="Evet/Hayır",IF(OR(E13="Var",E13="Yapıldı",E13="Evet"),'1 AYAR'!$E$4,0),IF(LEN(E13)>3,'1 AYAR'!$E$4,0)))) | H13: =IF($D13<>"Evet","",IF('1 AYAR'!$C$5="Sayı",MIN(G13*'1 AYAR'!$D$5,'1 AYAR'!$E$5),IF('1 AYAR'!$C$5="Evet/Hayır",IF(OR(G13="Var",G13="Yapıldı",G13="Evet"),'1 AYAR'!$E$5,0),IF(LEN(G13)>3,'1 AYAR'!$E$5,0)))) | J13: =IF($D13<>"Evet","",IF('1 AYAR'!$C$6="Sayı",MIN(I13*'1 AYAR'!$D$6,'1 AYAR'!$E$6),IF('1 AYAR'!$C$6="Evet/Hayır",IF(OR(I13="Var",I13="Yapıldı",I13="Evet"),'1 AYAR'!$E$6,0),IF(LEN(I13)>3,'1 AYAR'!$E$6,0)))) | L13: =IF($D13<>"Evet","",IF('1 AYAR'!$C$7="Sayı",MIN(K13*'1 AYAR'!$D$7,'1 AYAR'!$E$7),IF('1 AYAR'!$C$7="Evet/Hayır",IF(OR(K13="Var",K13="Yapıldı",K13="Evet"),'1 AYAR'!$E$7,0),IF(LEN(K13)>3,'1 AYAR'!$E$7,0)))) | N13: =IF($D13<>"Evet","",IF('1 AYAR'!$C$8="Sayı",MIN(M13*'1 AYAR'!$D$8,'1 AYAR'!$E$8),IF('1 AYAR'!$C$8="Evet/Hayır",IF(OR(M13="Var",M13="Yapıldı",M13="Evet"),'1 AYAR'!$E$8,0),IF(LEN(M13)>3,'1 AYAR'!$E$8,0)))) | P13: =IF($D13<>"Evet","",IF('1 AYAR'!$C$9="Sayı",MIN(O13*'1 AYAR'!$D$9,'1 AYAR'!$E$9),IF('1 AYAR'!$C$9="Evet/Hayır",IF(OR(O13="Var",O13="Yapıldı",O13="Evet"),'1 AYAR'!$E$9,0),IF(LEN(O13)>3,'1 AYAR'!$E$9,0)))) | R13: =IF($D13<>"Evet","",IF('1 AYAR'!$C$10="Sayı",MIN(Q13*'1 AYAR'!$D$10,'1 AYAR'!$E$10),IF('1 AYAR'!$C$10="Evet/Hayır",IF(OR(Q13="Var",Q13="Yapıldı",Q13="Evet"),'1 AYAR'!$E$10,0),IF(LEN(Q13)>3,'1 AYAR'!$E$10,0)))) | T13: =IF($D13<>"Evet","",IF('1 AYAR'!$C$11="Sayı",MIN(S13*'1 AYAR'!$D$11,'1 AYAR'!$E$11),IF('1 AYAR'!$C$11="Evet/Hayır",IF(OR(S13="Var",S13="Yapıldı",S13="Evet"),'1 AYAR'!$E$11,0),IF(LEN(S13)>3,'1 AYAR'!$E$11,0)))) | V13: =IF($D13<>"Evet","",IF('1 AYAR'!$C$12="Sayı",MIN(U13*'1 AYAR'!$D$12,'1 AYAR'!$E$12),IF('1 AYAR'!$C$12="Evet/Hayır",IF(OR(U13="Var",U13="Yapıldı",U13="Evet"),'1 AYAR'!$E$12,0),IF(LEN(U13)>3,'1 AYAR'!$E$12,0)))) | X13: =IF($D13<>"Evet","",IF('1 AYAR'!$C$13="Sayı",MIN(W13*'1 AYAR'!$D$13,'1 AYAR'!$E$13),IF('1 AYAR'!$C$13="Evet/Hayır",IF(OR(W13="Var",W13="Yapıldı",W13="Evet"),'1 AYAR'!$E$13,0),IF(LEN(W13)>3,'1 AYAR'!$E$13,0)))) | Z13: =IF($D13<>"Evet","",IF('1 AYAR'!$C$14="Sayı",MIN(Y13*'1 AYAR'!$D$14,'1 AYAR'!$E$14),IF('1 AYAR'!$C$14="Evet/Hayır",IF(OR(Y13="Var",Y13="Yapıldı",Y13="Evet"),'1 AYAR'!$E$14,0),IF(LEN(Y13)>3,'1 AYAR'!$E$14,0)))) | AB13: =IF($D13<>"Evet","",IF('1 AYAR'!$C$15="Sayı",MIN(AA13*'1 AYAR'!$D$15,'1 AYAR'!$E$15),IF('1 AYAR'!$C$15="Evet/Hayır",IF(OR(AA13="Var",AA13="Yapıldı",AA13="Evet"),'1 AYAR'!$E$15,0),IF(LEN(AA13)>3,'1 AYAR'!$E$15,0)))) | AC13: =IF($D13<>"Evet","",F13+H13+J13+L13+N13+P13+R13+T13+V13+X13+Z13+AB13) | AD13: =IF($D13<>"Evet","",IF(AC13>='1 AYAR'!$C$27,"A",IF(AC13>='1 AYAR'!$C$28,"B",IF(AC13>='1 AYAR'!$C$29,"C","D")))) | AE13: =IF($D13<>"Evet","",AC13+ROW()/10000)
A14: =IF($D14<>"Evet","",RANK(AC14,$AC$6:$AC$44,0)) | B14: B1 HALİÇ HATTI | C14: Sarıyer | D14: Hayır | F14: =IF($D14<>"Evet","",IF('1 AYAR'!$C$4="Sayı",MIN(E14*'1 AYAR'!$D$4,'1 AYAR'!$E$4),IF('1 AYAR'!$C$4="Evet/Hayır",IF(OR(E14="Var",E14="Yapıldı",E14="Evet"),'1 AYAR'!$E$4,0),IF(LEN(E14)>3,'1 AYAR'!$E$4,0)))) | H14: =IF($D14<>"Evet","",IF('1 AYAR'!$C$5="Sayı",MIN(G14*'1 AYAR'!$D$5,'1 AYAR'!$E$5),IF('1 AYAR'!$C$5="Evet/Hayır",IF(OR(G14="Var",G14="Yapıldı",G14="Evet"),'1 AYAR'!$E$5,0),IF(LEN(G14)>3,'1 AYAR'!$E$5,0)))) | J14: =IF($D14<>"Evet","",IF('1 AYAR'!$C$6="Sayı",MIN(I14*'1 AYAR'!$D$6,'1 AYAR'!$E$6),IF('1 AYAR'!$C$6="Evet/Hayır",IF(OR(I14="Var",I14="Yapıldı",I14="Evet"),'1 AYAR'!$E$6,0),IF(LEN(I14)>3,'1 AYAR'!$E$6,0)))) | L14: =IF($D14<>"Evet","",IF('1 AYAR'!$C$7="Sayı",MIN(K14*'1 AYAR'!$D$7,'1 AYAR'!$E$7),IF('1 AYAR'!$C$7="Evet/Hayır",IF(OR(K14="Var",K14="Yapıldı",K14="Evet"),'1 AYAR'!$E$7,0),IF(LEN(K14)>3,'1 AYAR'!$E$7,0)))) | N14: =IF($D14<>"Evet","",IF('1 AYAR'!$C$8="Sayı",MIN(M14*'1 AYAR'!$D$8,'1 AYAR'!$E$8),IF('1 AYAR'!$C$8="Evet/Hayır",IF(OR(M14="Var",M14="Yapıldı",M14="Evet"),'1 AYAR'!$E$8,0),IF(LEN(M14)>3,'1 AYAR'!$E$8,0)))) | P14: =IF($D14<>"Evet","",IF('1 AYAR'!$C$9="Sayı",MIN(O14*'1 AYAR'!$D$9,'1 AYAR'!$E$9),IF('1 AYAR'!$C$9="Evet/Hayır",IF(OR(O14="Var",O14="Yapıldı",O14="Evet"),'1 AYAR'!$E$9,0),IF(LEN(O14)>3,'1 AYAR'!$E$9,0)))) | R14: =IF($D14<>"Evet","",IF('1 AYAR'!$C$10="Sayı",MIN(Q14*'1 AYAR'!$D$10,'1 AYAR'!$E$10),IF('1 AYAR'!$C$10="Evet/Hayır",IF(OR(Q14="Var",Q14="Yapıldı",Q14="Evet"),'1 AYAR'!$E$10,0),IF(LEN(Q14)>3,'1 AYAR'!$E$10,0)))) | T14: =IF($D14<>"Evet","",IF('1 AYAR'!$C$11="Sayı",MIN(S14*'1 AYAR'!$D$11,'1 AYAR'!$E$11),IF('1 AYAR'!$C$11="Evet/Hayır",IF(OR(S14="Var",S14="Yapıldı",S14="Evet"),'1 AYAR'!$E$11,0),IF(LEN(S14)>3,'1 AYAR'!$E$11,0)))) | V14: =IF($D14<>"Evet","",IF('1 AYAR'!$C$12="Sayı",MIN(U14*'1 AYAR'!$D$12,'1 AYAR'!$E$12),IF('1 AYAR'!$C$12="Evet/Hayır",IF(OR(U14="Var",U14="Yapıldı",U14="Evet"),'1 AYAR'!$E$12,0),IF(LEN(U14)>3,'1 AYAR'!$E$12,0)))) | X14: =IF($D14<>"Evet","",IF('1 AYAR'!$C$13="Sayı",MIN(W14*'1 AYAR'!$D$13,'1 AYAR'!$E$13),IF('1 AYAR'!$C$13="Evet/Hayır",IF(OR(W14="Var",W14="Yapıldı",W14="Evet"),'1 AYAR'!$E$13,0),IF(LEN(W14)>3,'1 AYAR'!$E$13,0)))) | Z14: =IF($D14<>"Evet","",IF('1 AYAR'!$C$14="Sayı",MIN(Y14*'1 AYAR'!$D$14,'1 AYAR'!$E$14),IF('1 AYAR'!$C$14="Evet/Hayır",IF(OR(Y14="Var",Y14="Yapıldı",Y14="Evet"),'1 AYAR'!$E$14,0),IF(LEN(Y14)>3,'1 AYAR'!$E$14,0)))) | AB14: =IF($D14<>"Evet","",IF('1 AYAR'!$C$15="Sayı",MIN(AA14*'1 AYAR'!$D$15,'1 AYAR'!$E$15),IF('1 AYAR'!$C$15="Evet/Hayır",IF(OR(AA14="Var",AA14="Yapıldı",AA14="Evet"),'1 AYAR'!$E$15,0),IF(LEN(AA14)>3,'1 AYAR'!$E$15,0)))) | AC14: =IF($D14<>"Evet","",F14+H14+J14+L14+N14+P14+R14+T14+V14+X14+Z14+AB14) | AD14: =IF($D14<>"Evet","",IF(AC14>='1 AYAR'!$C$27,"A",IF(AC14>='1 AYAR'!$C$28,"B",IF(AC14>='1 AYAR'!$C$29,"C","D")))) | AE14: =IF($D14<>"Evet","",AC14+ROW()/10000)
A15: =IF($D15<>"Evet","",RANK(AC15,$AC$6:$AC$44,0)) | B15: B1 HALİÇ HATTI | C15: Beşiktaş | D15: Hayır | F15: =IF($D15<>"Evet","",IF('1 AYAR'!$C$4="Sayı",MIN(E15*'1 AYAR'!$D$4,'1 AYAR'!$E$4),IF('1 AYAR'!$C$4="Evet/Hayır",IF(OR(E15="Var",E15="Yapıldı",E15="Evet"),'1 AYAR'!$E$4,0),IF(LEN(E15)>3,'1 AYAR'!$E$4,0)))) | H15: =IF($D15<>"Evet","",IF('1 AYAR'!$C$5="Sayı",MIN(G15*'1 AYAR'!$D$5,'1 AYAR'!$E$5),IF('1 AYAR'!$C$5="Evet/Hayır",IF(OR(G15="Var",G15="Yapıldı",G15="Evet"),'1 AYAR'!$E$5,0),IF(LEN(G15)>3,'1 AYAR'!$E$5,0)))) | J15: =IF($D15<>"Evet","",IF('1 AYAR'!$C$6="Sayı",MIN(I15*'1 AYAR'!$D$6,'1 AYAR'!$E$6),IF('1 AYAR'!$C$6="Evet/Hayır",IF(OR(I15="Var",I15="Yapıldı",I15="Evet"),'1 AYAR'!$E$6,0),IF(LEN(I15)>3,'1 AYAR'!$E$6,0)))) | L15: =IF($D15<>"Evet","",IF('1 AYAR'!$C$7="Sayı",MIN(K15*'1 AYAR'!$D$7,'1 AYAR'!$E$7),IF('1 AYAR'!$C$7="Evet/Hayır",IF(OR(K15="Var",K15="Yapıldı",K15="Evet"),'1 AYAR'!$E$7,0),IF(LEN(K15)>3,'1 AYAR'!$E$7,0)))) | N15: =IF($D15<>"Evet","",IF('1 AYAR'!$C$8="Sayı",MIN(M15*'1 AYAR'!$D$8,'1 AYAR'!$E$8),IF('1 AYAR'!$C$8="Evet/Hayır",IF(OR(M15="Var",M15="Yapıldı",M15="Evet"),'1 AYAR'!$E$8,0),IF(LEN(M15)>3,'1 AYAR'!$E$8,0)))) | P15: =IF($D15<>"Evet","",IF('1 AYAR'!$C$9="Sayı",MIN(O15*'1 AYAR'!$D$9,'1 AYAR'!$E$9),IF('1 AYAR'!$C$9="Evet/Hayır",IF(OR(O15="Var",O15="Yapıldı",O15="Evet"),'1 AYAR'!$E$9,0),IF(LEN(O15)>3,'1 AYAR'!$E$9,0)))) | R15: =IF($D15<>"Evet","",IF('1 AYAR'!$C$10="Sayı",MIN(Q15*'1 AYAR'!$D$10,'1 AYAR'!$E$10),IF('1 AYAR'!$C$10="Evet/Hayır",IF(OR(Q15="Var",Q15="Yapıldı",Q15="Evet"),'1 AYAR'!$E$10,0),IF(LEN(Q15)>3,'1 AYAR'!$E$10,0)))) | T15: =IF($D15<>"Evet","",IF('1 AYAR'!$C$11="Sayı",MIN(S15*'1 AYAR'!$D$11,'1 AYAR'!$E$11),IF('1 AYAR'!$C$11="Evet/Hayır",IF(OR(S15="Var",S15="Yapıldı",S15="Evet"),'1 AYAR'!$E$11,0),IF(LEN(S15)>3,'1 AYAR'!$E$11,0)))) | V15: =IF($D15<>"Evet","",IF('1 AYAR'!$C$12="Sayı",MIN(U15*'1 AYAR'!$D$12,'1 AYAR'!$E$12),IF('1 AYAR'!$C$12="Evet/Hayır",IF(OR(U15="Var",U15="Yapıldı",U15="Evet"),'1 AYAR'!$E$12,0),IF(LEN(U15)>3,'1 AYAR'!$E$12,0)))) | X15: =IF($D15<>"Evet","",IF('1 AYAR'!$C$13="Sayı",MIN(W15*'1 AYAR'!$D$13,'1 AYAR'!$E$13),IF('1 AYAR'!$C$13="Evet/Hayır",IF(OR(W15="Var",W15="Yapıldı",W15="Evet"),'1 AYAR'!$E$13,0),IF(LEN(W15)>3,'1 AYAR'!$E$13,0)))) | Z15: =IF($D15<>"Evet","",IF('1 AYAR'!$C$14="Sayı",MIN(Y15*'1 AYAR'!$D$14,'1 AYAR'!$E$14),IF('1 AYAR'!$C$14="Evet/Hayır",IF(OR(Y15="Var",Y15="Yapıldı",Y15="Evet"),'1 AYAR'!$E$14,0),IF(LEN(Y15)>3,'1 AYAR'!$E$14,0)))) | AB15: =IF($D15<>"Evet","",IF('1 AYAR'!$C$15="Sayı",MIN(AA15*'1 AYAR'!$D$15,'1 AYAR'!$E$15),IF('1 AYAR'!$C$15="Evet/Hayır",IF(OR(AA15="Var",AA15="Yapıldı",AA15="Evet"),'1 AYAR'!$E$15,0),IF(LEN(AA15)>3,'1 AYAR'!$E$15,0)))) | AC15: =IF($D15<>"Evet","",F15+H15+J15+L15+N15+P15+R15+T15+V15+X15+Z15+AB15) | AD15: =IF($D15<>"Evet","",IF(AC15>='1 AYAR'!$C$27,"A",IF(AC15>='1 AYAR'!$C$28,"B",IF(AC15>='1 AYAR'!$C$29,"C","D")))) | AE15: =IF($D15<>"Evet","",AC15+ROW()/10000)
A16: =IF($D16<>"Evet","",RANK(AC16,$AC$6:$AC$44,0)) -> 6 | B16: B2 TRAKYA HATTI | C16: Bağcılar | D16: Evet | E16: 8 | F16: =IF($D16<>"Evet","",IF('1 AYAR'!$C$4="Sayı",MIN(E16*'1 AYAR'!$D$4,'1 AYAR'!$E$4),IF('1 AYAR'!$C$4="Evet/Hayır",IF(OR(E16="Var",E16="Yapıldı",E16="Evet"),'1 AYAR'!$E$4,0),IF(LEN(E16)>3,'1 AYAR'!$E$4,0)))) -> 8 | G16: 4 | H16: =IF($D16<>"Evet","",IF('1 AYAR'!$C$5="Sayı",MIN(G16*'1 AYAR'!$D$5,'1 AYAR'!$E$5),IF('1 AYAR'!$C$5="Evet/Hayır",IF(OR(G16="Var",G16="Yapıldı",G16="Evet"),'1 AYAR'!$E$5,0),IF(LEN(G16)>3,'1 AYAR'!$E$5,0)))) -> 10 | I16: Var | J16: =IF($D16<>"Evet","",IF('1 AYAR'!$C$6="Sayı",MIN(I16*'1 AYAR'!$D$6,'1 AYAR'!$E$6),IF('1 AYAR'!$C$6="Evet/Hayır",IF(OR(I16="Var",I16="Yapıldı",I16="Evet"),'1 AYAR'!$E$6,0),IF(LEN(I16)>3,'1 AYAR'!$E$6,0)))) -> 5 | K16: 20 | L16: =IF($D16<>"Evet","",IF('1 AYAR'!$C$7="Sayı",MIN(K16*'1 AYAR'!$D$7,'1 AYAR'!$E$7),IF('1 AYAR'!$C$7="Evet/Hayır",IF(OR(K16="Var",K16="Yapıldı",K16="Evet"),'1 AYAR'!$E$7,0),IF(LEN(K16)>3,'1 AYAR'!$E$7,0)))) -> 10 | M16: 0 | N16: =IF($D16<>"Evet","",IF('1 AYAR'!$C$8="Sayı",MIN(M16*'1 AYAR'!$D$8,'1 AYAR'!$E$8),IF('1 AYAR'!$C$8="Evet/Hayır",IF(OR(M16="Var",M16="Yapıldı",M16="Evet"),'1 AYAR'!$E$8,0),IF(LEN(M16)>3,'1 AYAR'!$E$8,0)))) -> 0 | O16: Yapılmadı | P16: =IF($D16<>"Evet","",IF('1 AYAR'!$C$9="Sayı",MIN(O16*'1 AYAR'!$D$9,'1 AYAR'!$E$9),IF('1 AYAR'!$C$9="Evet/Hayır",IF(OR(O16="Var",O16="Yapıldı",O16="Evet"),'1 AYAR'!$E$9,0),IF(LEN(O16)>3,'1 AYAR'!$E$9,0)))) -> 0 | Q16: Yapılmadı | R16: =IF($D16<>"Evet","",IF('1 AYAR'!$C$10="Sayı",MIN(Q16*'1 AYAR'!$D$10,'1 AYAR'!$E$10),IF('1 AYAR'!$C$10="Evet/Hayır",IF(OR(Q16="Var",Q16="Yapıldı",Q16="Evet"),'1 AYAR'!$E$10,0),IF(LEN(Q16)>3,'1 AYAR'!$E$10,0)))) -> 0 | S16: 0 | T16: =IF($D16<>"Evet","",IF('1 AYAR'!$C$11="Sayı",MIN(S16*'1 AYAR'!$D$11,'1 AYAR'!$E$11),IF('1 AYAR'!$C$11="Evet/Hayır",IF(OR(S16="Var",S16="Yapıldı",S16="Evet"),'1 AYAR'!$E$11,0),IF(LEN(S16)>3,'1 AYAR'!$E$11,0)))) -> 0 | U16: 0 | V16: =IF($D16<>"Evet","",IF('1 AYAR'!$C$12="Sayı",MIN(U16*'1 AYAR'!$D$12,'1 AYAR'!$E$12),IF('1 AYAR'!$C$12="Evet/Hayır",IF(OR(U16="Var",U16="Yapıldı",U16="Evet"),'1 AYAR'!$E$12,0),IF(LEN(U16)>3,'1 AYAR'!$E$12,0)))) -> 0 | W16: 1 | X16: =IF($D16<>"Evet","",IF('1 AYAR'!$C$13="Sayı",MIN(W16*'1 AYAR'!$D$13,'1 AYAR'!$E$13),IF('1 AYAR'!$C$13="Evet/Hayır",IF(OR(W16="Var",W16="Yapıldı",W16="Evet"),'1 AYAR'!$E$13,0),IF(LEN(W16)>3,'1 AYAR'!$E$13,0)))) -> 1 | Y16: 2 | Z16: =IF($D16<>"Evet","",IF('1 AYAR'!$C$14="Sayı",MIN(Y16*'1 AYAR'!$D$14,'1 AYAR'!$E$14),IF('1 AYAR'!$C$14="Evet/Hayır",IF(OR(Y16="Var",Y16="Yapıldı",Y16="Evet"),'1 AYAR'!$E$14,0),IF(LEN(Y16)>3,'1 AYAR'!$E$14,0)))) -> 2 | AB16: =IF($D16<>"Evet","",IF('1 AYAR'!$C$15="Sayı",MIN(AA16*'1 AYAR'!$D$15,'1 AYAR'!$E$15),IF('1 AYAR'!$C$15="Evet/Hayır",IF(OR(AA16="Var",AA16="Yapıldı",AA16="Evet"),'1 AYAR'!$E$15,0),IF(LEN(AA16)>3,'1 AYAR'!$E$15,0)))) -> 0 | AC16: =IF($D16<>"Evet","",F16+H16+J16+L16+N16+P16+R16+T16+V16+X16+Z16+AB16) -> 36 | AD16: =IF($D16<>"Evet","",IF(AC16>='1 AYAR'!$C$27,"A",IF(AC16>='1 AYAR'!$C$28,"B",IF(AC16>='1 AYAR'!$C$29,"C","D")))) -> C | AE16: =IF($D16<>"Evet","",AC16+ROW()/10000) -> 36.0016
A17: =IF($D17<>"Evet","",RANK(AC17,$AC$6:$AC$44,0)) -> 1 | B17: B2 TRAKYA HATTI | C17: Bahçelievler | D17: Evet | E17: 20 | F17: =IF($D17<>"Evet","",IF('1 AYAR'!$C$4="Sayı",MIN(E17*'1 AYAR'!$D$4,'1 AYAR'!$E$4),IF('1 AYAR'!$C$4="Evet/Hayır",IF(OR(E17="Var",E17="Yapıldı",E17="Evet"),'1 AYAR'!$E$4,0),IF(LEN(E17)>3,'1 AYAR'!$E$4,0)))) -> 20 | G17: 4 | H17: =IF($D17<>"Evet","",IF('1 AYAR'!$C$5="Sayı",MIN(G17*'1 AYAR'!$D$5,'1 AYAR'!$E$5),IF('1 AYAR'!$C$5="Evet/Hayır",IF(OR(G17="Var",G17="Yapıldı",G17="Evet"),'1 AYAR'!$E$5,0),IF(LEN(G17)>3,'1 AYAR'!$E$5,0)))) -> 10 | I17: Yok | J17: =IF($D17<>"Evet","",IF('1 AYAR'!$C$6="Sayı",MIN(I17*'1 AYAR'!$D$6,'1 AYAR'!$E$6),IF('1 AYAR'!$C$6="Evet/Hayır",IF(OR(I17="Var",I17="Yapıldı",I17="Evet"),'1 AYAR'!$E$6,0),IF(LEN(I17)>3,'1 AYAR'!$E$6,0)))) -> 0 | K17: 20 | L17: =IF($D17<>"Evet","",IF('1 AYAR'!$C$7="Sayı",MIN(K17*'1 AYAR'!$D$7,'1 AYAR'!$E$7),IF('1 AYAR'!$C$7="Evet/Hayır",IF(OR(K17="Var",K17="Yapıldı",K17="Evet"),'1 AYAR'!$E$7,0),IF(LEN(K17)>3,'1 AYAR'!$E$7,0)))) -> 10 | M17: 10 | N17: =IF($D17<>"Evet","",IF('1 AYAR'!$C$8="Sayı",MIN(M17*'1 AYAR'!$D$8,'1 AYAR'!$E$8),IF('1 AYAR'!$C$8="Evet/Hayır",IF(OR(M17="Var",M17="Yapıldı",M17="Evet"),'1 AYAR'!$E$8,0),IF(LEN(M17)>3,'1 AYAR'!$E$8,0)))) -> 10 | O17: Yapılmadı | P17: =IF($D17<>"Evet","",IF('1 AYAR'!$C$9="Sayı",MIN(O17*'1 AYAR'!$D$9,'1 AYAR'!$E$9),IF('1 AYAR'!$C$9="Evet/Hayır",IF(OR(O17="Var",O17="Yapıldı",O17="Evet"),'1 AYAR'!$E$9,0),IF(LEN(O17)>3,'1 AYAR'!$E$9,0)))) -> 0 | Q17: Yapılmadı | R17: =IF($D17<>"Evet","",IF('1 AYAR'!$C$10="Sayı",MIN(Q17*'1 AYAR'!$D$10,'1 AYAR'!$E$10),IF('1 AYAR'!$C$10="Evet/Hayır",IF(OR(Q17="Var",Q17="Yapıldı",Q17="Evet"),'1 AYAR'!$E$10,0),IF(LEN(Q17)>3,'1 AYAR'!$E$10,0)))) -> 0 | S17: 2 | T17: =IF($D17<>"Evet","",IF('1 AYAR'!$C$11="Sayı",MIN(S17*'1 AYAR'!$D$11,'1 AYAR'!$E$11),IF('1 AYAR'!$C$11="Evet/Hayır",IF(OR(S17="Var",S17="Yapıldı",S17="Evet"),'1 AYAR'!$E$11,0),IF(LEN(S17)>3,'1 AYAR'!$E$11,0)))) -> 2 | U17: 2 | V17: =IF($D17<>"Evet","",IF('1 AYAR'!$C$12="Sayı",MIN(U17*'1 AYAR'!$D$12,'1 AYAR'!$E$12),IF('1 AYAR'!$C$12="Evet/Hayır",IF(OR(U17="Var",U17="Yapıldı",U17="Evet"),'1 AYAR'!$E$12,0),IF(LEN(U17)>3,'1 AYAR'!$E$12,0)))) -> 2 | W17: 0 | X17: =IF($D17<>"Evet","",IF('1 AYAR'!$C$13="Sayı",MIN(W17*'1 AYAR'!$D$13,'1 AYAR'!$E$13),IF('1 AYAR'!$C$13="Evet/Hayır",IF(OR(W17="Var",W17="Yapıldı",W17="Evet"),'1 AYAR'!$E$13,0),IF(LEN(W17)>3,'1 AYAR'!$E$13,0)))) -> 0 | Y17: 4 | Z17: =IF($D17<>"Evet","",IF('1 AYAR'!$C$14="Sayı",MIN(Y17*'1 AYAR'!$D$14,'1 AYAR'!$E$14),IF('1 AYAR'!$C$14="Evet/Hayır",IF(OR(Y17="Var",Y17="Yapıldı",Y17="Evet"),'1 AYAR'!$E$14,0),IF(LEN(Y17)>3,'1 AYAR'!$E$14,0)))) -> 4 | AA17: Ramazan faaliyetleri; öğrencilerle cami buluşması; 50 öğrenciye iftar | AB17: =IF($D17<>"Evet","",IF('1 AYAR'!$C$15="Sayı",MIN(AA17*'1 AYAR'!$D$15,'1 AYAR'!$E$15),IF('1 AYAR'!$C$15="Evet/Hayır",IF(OR(AA17="Var",AA17="Yapıldı",AA17="Evet"),'1 AYAR'!$E$15,0),IF(LEN(AA17)>3,'1 AYAR'!$E$15,0)))) -> 5 | AC17: =IF($D17<>"Evet","",F17+H17+J17+L17+N17+P17+R17+T17+V17+X17+Z17+AB17) -> 63 | AD17: =IF($D17<>"Evet","",IF(AC17>='1 AYAR'!$C$27,"A",IF(AC17>='1 AYAR'!$C$28,"B",IF(AC17>='1 AYAR'!$C$29,"C","D")))) -> B | AE17: =IF($D17<>"Evet","",AC17+ROW()/10000) -> 63.0017
A18: =IF($D18<>"Evet","",RANK(AC18,$AC$6:$AC$44,0)) -> 2 | B18: B2 TRAKYA HATTI | C18: Esenler | D18: Evet | E18: 10 | F18: =IF($D18<>"Evet","",IF('1 AYAR'!$C$4="Sayı",MIN(E18*'1 AYAR'!$D$4,'1 AYAR'!$E$4),IF('1 AYAR'!$C$4="Evet/Hayır",IF(OR(E18="Var",E18="Yapıldı",E18="Evet"),'1 AYAR'!$E$4,0),IF(LEN(E18)>3,'1 AYAR'!$E$4,0)))) -> 10 | G18: 3 | H18: =IF($D18<>"Evet","",IF('1 AYAR'!$C$5="Sayı",MIN(G18*'1 AYAR'!$D$5,'1 AYAR'!$E$5),IF('1 AYAR'!$C$5="Evet/Hayır",IF(OR(G18="Var",G18="Yapıldı",G18="Evet"),'1 AYAR'!$E$5,0),IF(LEN(G18)>3,'1 AYAR'!$E$5,0)))) -> 7.5 | I18: Var | J18: =IF($D18<>"Evet","",IF('1 AYAR'!$C$6="Sayı",MIN(I18*'1 AYAR'!$D$6,'1 AYAR'!$E$6),IF('1 AYAR'!$C$6="Evet/Hayır",IF(OR(I18="Var",I18="Yapıldı",I18="Evet"),'1 AYAR'!$E$6,0),IF(LEN(I18)>3,'1 AYAR'!$E$6,0)))) -> 5 | K18: 15 | L18: =IF($D18<>"Evet","",IF('1 AYAR'!$C$7="Sayı",MIN(K18*'1 AYAR'!$D$7,'1 AYAR'!$E$7),IF('1 AYAR'!$C$7="Evet/Hayır",IF(OR(K18="Var",K18="Yapıldı",K18="Evet"),'1 AYAR'!$E$7,0),IF(LEN(K18)>3,'1 AYAR'!$E$7,0)))) -> 7.5 | M18: 2 | N18: =IF($D18<>"Evet","",IF('1 AYAR'!$C$8="Sayı",MIN(M18*'1 AYAR'!$D$8,'1 AYAR'!$E$8),IF('1 AYAR'!$C$8="Evet/Hayır",IF(OR(M18="Var",M18="Yapıldı",M18="Evet"),'1 AYAR'!$E$8,0),IF(LEN(M18)>3,'1 AYAR'!$E$8,0)))) -> 2 | O18: Yapılmadı | P18: =IF($D18<>"Evet","",IF('1 AYAR'!$C$9="Sayı",MIN(O18*'1 AYAR'!$D$9,'1 AYAR'!$E$9),IF('1 AYAR'!$C$9="Evet/Hayır",IF(OR(O18="Var",O18="Yapıldı",O18="Evet"),'1 AYAR'!$E$9,0),IF(LEN(O18)>3,'1 AYAR'!$E$9,0)))) -> 0 | Q18: Yapıldı | R18: =IF($D18<>"Evet","",IF('1 AYAR'!$C$10="Sayı",MIN(Q18*'1 AYAR'!$D$10,'1 AYAR'!$E$10),IF('1 AYAR'!$C$10="Evet/Hayır",IF(OR(Q18="Var",Q18="Yapıldı",Q18="Evet"),'1 AYAR'!$E$10,0),IF(LEN(Q18)>3,'1 AYAR'!$E$10,0)))) -> 10 | S18: 0 | T18: =IF($D18<>"Evet","",IF('1 AYAR'!$C$11="Sayı",MIN(S18*'1 AYAR'!$D$11,'1 AYAR'!$E$11),IF('1 AYAR'!$C$11="Evet/Hayır",IF(OR(S18="Var",S18="Yapıldı",S18="Evet"),'1 AYAR'!$E$11,0),IF(LEN(S18)>3,'1 AYAR'!$E$11,0)))) -> 0 | U18: 1 | V18: =IF($D18<>"Evet","",IF('1 AYAR'!$C$12="Sayı",MIN(U18*'1 AYAR'!$D$12,'1 AYAR'!$E$12),IF('1 AYAR'!$C$12="Evet/Hayır",IF(OR(U18="Var",U18="Yapıldı",U18="Evet"),'1 AYAR'!$E$12,0),IF(LEN(U18)>3,'1 AYAR'!$E$12,0)))) -> 1 | W18: 5 | X18: =IF($D18<>"Evet","",IF('1 AYAR'!$C$13="Sayı",MIN(W18*'1 AYAR'!$D$13,'1 AYAR'!$E$13),IF('1 AYAR'!$C$13="Evet/Hayır",IF(OR(W18="Var",W18="Yapıldı",W18="Evet"),'1 AYAR'!$E$13,0),IF(LEN(W18)>3,'1 AYAR'!$E$13,0)))) -> 5 | Y18: 6 | Z18: =IF($D18<>"Evet","",IF('1 AYAR'!$C$14="Sayı",MIN(Y18*'1 AYAR'!$D$14,'1 AYAR'!$E$14),IF('1 AYAR'!$C$14="Evet/Hayır",IF(OR(Y18="Var",Y18="Yapıldı",Y18="Evet"),'1 AYAR'!$E$14,0),IF(LEN(Y18)>3,'1 AYAR'!$E$14,0)))) -> 5 | AA18: Lise Ramazan İftarı | AB18: =IF($D18<>"Evet","",IF('1 AYAR'!$C$15="Sayı",MIN(AA18*'1 AYAR'!$D$15,'1 AYAR'!$E$15),IF('1 AYAR'!$C$15="Evet/Hayır",IF(OR(AA18="Var",AA18="Yapıldı",AA18="Evet"),'1 AYAR'!$E$15,0),IF(LEN(AA18)>3,'1 AYAR'!$E$15,0)))) -> 5 | AC18: =IF($D18<>"Evet","",F18+H18+J18+L18+N18+P18+R18+T18+V18+X18+Z18+AB18) -> 58 | AD18: =IF($D18<>"Evet","",IF(AC18>='1 AYAR'!$C$27,"A",IF(AC18>='1 AYAR'!$C$28,"B",IF(AC18>='1 AYAR'!$C$29,"C","D")))) -> B | AE18: =IF($D18<>"Evet","",AC18+ROW()/10000) -> 58.0018
A19: =IF($D19<>"Evet","",RANK(AC19,$AC$6:$AC$44,0)) | B19: B2 TRAKYA HATTI | C19: Güngören | D19: Hayır | F19: =IF($D19<>"Evet","",IF('1 AYAR'!$C$4="Sayı",MIN(E19*'1 AYAR'!$D$4,'1 AYAR'!$E$4),IF('1 AYAR'!$C$4="Evet/Hayır",IF(OR(E19="Var",E19="Yapıldı",E19="Evet"),'1 AYAR'!$E$4,0),IF(LEN(E19)>3,'1 AYAR'!$E$4,0)))) | H19: =IF($D19<>"Evet","",IF('1 AYAR'!$C$5="Sayı",MIN(G19*'1 AYAR'!$D$5,'1 AYAR'!$E$5),IF('1 AYAR'!$C$5="Evet/Hayır",IF(OR(G19="Var",G19="Yapıldı",G19="Evet"),'1 AYAR'!$E$5,0),IF(LEN(G19)>3,'1 AYAR'!$E$5,0)))) | J19: =IF($D19<>"Evet","",IF('1 AYAR'!$C$6="Sayı",MIN(I19*'1 AYAR'!$D$6,'1 AYAR'!$E$6),IF('1 AYAR'!$C$6="Evet/Hayır",IF(OR(I19="Var",I19="Yapıldı",I19="Evet"),'1 AYAR'!$E$6,0),IF(LEN(I19)>3,'1 AYAR'!$E$6,0)))) | L19: =IF($D19<>"Evet","",IF('1 AYAR'!$C$7="Sayı",MIN(K19*'1 AYAR'!$D$7,'1 AYAR'!$E$7),IF('1 AYAR'!$C$7="Evet/Hayır",IF(OR(K19="Var",K19="Yapıldı",K19="Evet"),'1 AYAR'!$E$7,0),IF(LEN(K19)>3,'1 AYAR'!$E$7,0)))) | N19: =IF($D19<>"Evet","",IF('1 AYAR'!$C$8="Sayı",MIN(M19*'1 AYAR'!$D$8,'1 AYAR'!$E$8),IF('1 AYAR'!$C$8="Evet/Hayır",IF(OR(M19="Var",M19="Yapıldı",M19="Evet"),'1 AYAR'!$E$8,0),IF(LEN(M19)>3,'1 AYAR'!$E$8,0)))) | P19: =IF($D19<>"Evet","",IF('1 AYAR'!$C$9="Sayı",MIN(O19*'1 AYAR'!$D$9,'1 AYAR'!$E$9),IF('1 AYAR'!$C$9="Evet/Hayır",IF(OR(O19="Var",O19="Yapıldı",O19="Evet"),'1 AYAR'!$E$9,0),IF(LEN(O19)>3,'1 AYAR'!$E$9,0)))) | R19: =IF($D19<>"Evet","",IF('1 AYAR'!$C$10="Sayı",MIN(Q19*'1 AYAR'!$D$10,'1 AYAR'!$E$10),IF('1 AYAR'!$C$10="Evet/Hayır",IF(OR(Q19="Var",Q19="Yapıldı",Q19="Evet"),'1 AYAR'!$E$10,0),IF(LEN(Q19)>3,'1 AYAR'!$E$10,0)))) | T19: =IF($D19<>"Evet","",IF('1 AYAR'!$C$11="Sayı",MIN(S19*'1 AYAR'!$D$11,'1 AYAR'!$E$11),IF('1 AYAR'!$C$11="Evet/Hayır",IF(OR(S19="Var",S19="Yapıldı",S19="Evet"),'1 AYAR'!$E$11,0),IF(LEN(S19)>3,'1 AYAR'!$E$11,0)))) | V19: =IF($D19<>"Evet","",IF('1 AYAR'!$C$12="Sayı",MIN(U19*'1 AYAR'!$D$12,'1 AYAR'!$E$12),IF('1 AYAR'!$C$12="Evet/Hayır",IF(OR(U19="Var",U19="Yapıldı",U19="Evet"),'1 AYAR'!$E$12,0),IF(LEN(U19)>3,'1 AYAR'!$E$12,0)))) | X19: =IF($D19<>"Evet","",IF('1 AYAR'!$C$13="Sayı",MIN(W19*'1 AYAR'!$D$13,'1 AYAR'!$E$13),IF('1 AYAR'!$C$13="Evet/Hayır",IF(OR(W19="Var",W19="Yapıldı",W19="Evet"),'1 AYAR'!$E$13,0),IF(LEN(W19)>3,'1 AYAR'!$E$13,0)))) | Z19: =IF($D19<>"Evet","",IF('1 AYAR'!$C$14="Sayı",MIN(Y19*'1 AYAR'!$D$14,'1 AYAR'!$E$14),IF('1 AYAR'!$C$14="Evet/Hayır",IF(OR(Y19="Var",Y19="Yapıldı",Y19="Evet"),'1 AYAR'!$E$14,0),IF(LEN(Y19)>3,'1 AYAR'!$E$14,0)))) | AB19: =IF($D19<>"Evet","",IF('1 AYAR'!$C$15="Sayı",MIN(AA19*'1 AYAR'!$D$15,'1 AYAR'!$E$15),IF('1 AYAR'!$C$15="Evet/Hayır",IF(OR(AA19="Var",AA19="Yapıldı",AA19="Evet"),'1 AYAR'!$E$15,0),IF(LEN(AA19)>3,'1 AYAR'!$E$15,0)))) | AC19: =IF($D19<>"Evet","",F19+H19+J19+L19+N19+P19+R19+T19+V19+X19+Z19+AB19) | AD19: =IF($D19<>"Evet","",IF(AC19>='1 AYAR'!$C$27,"A",IF(AC19>='1 AYAR'!$C$28,"B",IF(AC19>='1 AYAR'!$C$29,"C","D")))) | AE19: =IF($D19<>"Evet","",AC19+ROW()/10000)
A20: =IF($D20<>"Evet","",RANK(AC20,$AC$6:$AC$44,0)) | B20: B2 TRAKYA HATTI | C20: Küçükçekmece | D20: Hayır | F20: =IF($D20<>"Evet","",IF('1 AYAR'!$C$4="Sayı",MIN(E20*'1 AYAR'!$D$4,'1 AYAR'!$E$4),IF('1 AYAR'!$C$4="Evet/Hayır",IF(OR(E20="Var",E20="Yapıldı",E20="Evet"),'1 AYAR'!$E$4,0),IF(LEN(E20)>3,'1 AYAR'!$E$4,0)))) | H20: =IF($D20<>"Evet","",IF('1 AYAR'!$C$5="Sayı",MIN(G20*'1 AYAR'!$D$5,'1 AYAR'!$E$5),IF('1 AYAR'!$C$5="Evet/Hayır",IF(OR(G20="Var",G20="Yapıldı",G20="Evet"),'1 AYAR'!$E$5,0),IF(LEN(G20)>3,'1 AYAR'!$E$5,0)))) | J20: =IF($D20<>"Evet","",IF('1 AYAR'!$C$6="Sayı",MIN(I20*'1 AYAR'!$D$6,'1 AYAR'!$E$6),IF('1 AYAR'!$C$6="Evet/Hayır",IF(OR(I20="Var",I20="Yapıldı",I20="Evet"),'1 AYAR'!$E$6,0),IF(LEN(I20)>3,'1 AYAR'!$E$6,0)))) | L20: =IF($D20<>"Evet","",IF('1 AYAR'!$C$7="Sayı",MIN(K20*'1 AYAR'!$D$7,'1 AYAR'!$E$7),IF('1 AYAR'!$C$7="Evet/Hayır",IF(OR(K20="Var",K20="Yapıldı",K20="Evet"),'1 AYAR'!$E$7,0),IF(LEN(K20)>3,'1 AYAR'!$E$7,0)))) | N20: =IF($D20<>"Evet","",IF('1 AYAR'!$C$8="Sayı",MIN(M20*'1 AYAR'!$D$8,'1 AYAR'!$E$8),IF('1 AYAR'!$C$8="Evet/Hayır",IF(OR(M20="Var",M20="Yapıldı",M20="Evet"),'1 AYAR'!$E$8,0),IF(LEN(M20)>3,'1 AYAR'!$E$8,0)))) | P20: =IF($D20<>"Evet","",IF('1 AYAR'!$C$9="Sayı",MIN(O20*'1 AYAR'!$D$9,'1 AYAR'!$E$9),IF('1 AYAR'!$C$9="Evet/Hayır",IF(OR(O20="Var",O20="Yapıldı",O20="Evet"),'1 AYAR'!$E$9,0),IF(LEN(O20)>3,'1 AYAR'!$E$9,0)))) | R20: =IF($D20<>"Evet","",IF('1 AYAR'!$C$10="Sayı",MIN(Q20*'1 AYAR'!$D$10,'1 AYAR'!$E$10),IF('1 AYAR'!$C$10="Evet/Hayır",IF(OR(Q20="Var",Q20="Yapıldı",Q20="Evet"),'1 AYAR'!$E$10,0),IF(LEN(Q20)>3,'1 AYAR'!$E$10,0)))) | T20: =IF($D20<>"Evet","",IF('1 AYAR'!$C$11="Sayı",MIN(S20*'1 AYAR'!$D$11,'1 AYAR'!$E$11),IF('1 AYAR'!$C$11="Evet/Hayır",IF(OR(S20="Var",S20="Yapıldı",S20="Evet"),'1 AYAR'!$E$11,0),IF(LEN(S20)>3,'1 AYAR'!$E$11,0)))) | V20: =IF($D20<>"Evet","",IF('1 AYAR'!$C$12="Sayı",MIN(U20*'1 AYAR'!$D$12,'1 AYAR'!$E$12),IF('1 AYAR'!$C$12="Evet/Hayır",IF(OR(U20="Var",U20="Yapıldı",U20="Evet"),'1 AYAR'!$E$12,0),IF(LEN(U20)>3,'1 AYAR'!$E$12,0)))) | X20: =IF($D20<>"Evet","",IF('1 AYAR'!$C$13="Sayı",MIN(W20*'1 AYAR'!$D$13,'1 AYAR'!$E$13),IF('1 AYAR'!$C$13="Evet/Hayır",IF(OR(W20="Var",W20="Yapıldı",W20="Evet"),'1 AYAR'!$E$13,0),IF(LEN(W20)>3,'1 AYAR'!$E$13,0)))) | Z20: =IF($D20<>"Evet","",IF('1 AYAR'!$C$14="Sayı",MIN(Y20*'1 AYAR'!$D$14,'1 AYAR'!$E$14),IF('1 AYAR'!$C$14="Evet/Hayır",IF(OR(Y20="Var",Y20="Yapıldı",Y20="Evet"),'1 AYAR'!$E$14,0),IF(LEN(Y20)>3,'1 AYAR'!$E$14,0)))) | AB20: =IF($D20<>"Evet","",IF('1 AYAR'!$C$15="Sayı",MIN(AA20*'1 AYAR'!$D$15,'1 AYAR'!$E$15),IF('1 AYAR'!$C$15="Evet/Hayır",IF(OR(AA20="Var",AA20="Yapıldı",AA20="Evet"),'1 AYAR'!$E$15,0),IF(LEN(AA20)>3,'1 AYAR'!$E$15,0)))) | AC20: =IF($D20<>"Evet","",F20+H20+J20+L20+N20+P20+R20+T20+V20+X20+Z20+AB20) | AD20: =IF($D20<>"Evet","",IF(AC20>='1 AYAR'!$C$27,"A",IF(AC20>='1 AYAR'!$C$28,"B",IF(AC20>='1 AYAR'!$C$29,"C","D")))) | AE20: =IF($D20<>"Evet","",AC20+ROW()/10000)
